Workbook

Sheet Appendix A
B1: Enhet | C1: Case1 | D1: Case2 | E1: Case3 | F1: Case4 | G1: Case5 | H1: Case6 | I1: Case7 | J1: Case8 | N1: Absorber-høyder | P1: Stripper høyder
A2: CO2_IN | B2: dry % | C2: 3.52 | D2: 6.77 | E2: 7.41 | F2: 3.57 | G2: 3.9 | H2: 5.41 | I2: 4.57 | J2: 1.55 | N2: 1 | P2: 0
A3: CO2_OUT | B3: dry % | C3: 0.29 | D3: 1.19 | E3: 3.05 | F3: 0 | G3: 0.44 | H3: 3.09 | I3: 1.38 | J3: 0 | N3: 2 | P3: 1
A4: FT_100 | B4: kg/h | C4: 166.93 | D4: 172.33 | E4: 152.07 | F4: 142.13 | G4: 240.87 | H4: 178.72 | I4: 238.82 | J4: 239.09 | N4: 3 | P4: 2
A5: FT_101 | B5: kg/h | C5: 171.04 | D5: 179.79 | E5: 156.95 | F5: 146.43 | G5: 246.13 | H5: 180.31 | I5: 241.74 | J5: 240.34 | N5: 4 | P5: 3
A6: FT06 | B6: m³/h | C6: 89.77 | D6: 90.09 | E6: 127.02 | F6: 100.1 | G6: 125.94 | H6: 118.96 | I6: 118.87 | J6: 118.57 | N6: 5 | P6: 4
A7: FT_EH | B7: kg/h | C7: 2.91 | D7: 4.16 | E7: 4.6 | F7: 3.93 | G7: 5.56 | H7: 2.11 | I7: 3.49 | J7: 5.42 | N7: 6
A8: FT_EM | B8: kg/h | C8: 4.41 | D8: 7.71 | E8: 8.99 | F8: 6.53 | G8: 7.21 | H8: 4.95 | I8: 6.63 | J8: 3.25 | N8: 7
A9: FT_VASK | B9: kg/h | C9: 23.51 | D9: 23.21 | E9: 294.18 | F9: 271 | G9: 264.18 | H9: 196.66 | I9: 228.23 | J9: 251.49
A10: HE_04/05/06 | B10: kW | C10: 6.82 | D10: 9.23 | E10: 10.02 | F10: 8.29 | G10: 10.35 | H10: 6.13 | I10: 8.33 | J10: 8.26
A11: LT_01 | B11: L | C11: 11.32 | D11: 11.32 | E11: 11.32 | F11: 11.32 | G11: 11.67 | H11: 11.95 | I11: 11.95 | J11: 11.95
A12: LT_02 | B12: L | C12: 54.03 | D12: 53.31 | E12: 53.84 | F12: 53.67 | G12: 53.67 | H12: 54.75 | I12: 54.39 | J12: 54.4
A13: PI_100 | B13: mbar | C13: 1014.07 | D13: 1002.74 | E13: 1040.05 | F13: 1027.44 | G13: 1012.1 | H13: 1030.53 | I13: 1031.27 | J13: 1001.61
A14: PI_102 | B14: mbar | C14: 1019.19 | D14: 1005.78 | E14: 1048.13 | F14: 1032.3 | G14: 1020.73 | H14: 1038.75 | I14: 1041.48 | J14: 1010.21
A15: PI_103 | B15: mbar | C15: 1016.6 | D15: 1010.37 | E15: 1056.4 | F15: 1035.01 | G15: 1029 | H15: 1042.66 | I15: 1045.31 | J15: 1014.5
A16: PT_02 | B16: barg | C16: 0.9 | D16: 0.9 | E16: 0.9 | F16: 0.9 | G16: 0.9 | H16: 0.7 | I16: 0.7 | J16: 0.7
A17: PT_04 | B17: barg | C17: 0.89 | D17: 0.88 | E17: 0.88 | F17: 0.89 | G17: 0.88 | H17: 0.69 | I17: 0.68 | J17: 0.7
A18: PT11 | B18: L | C18: 6.48 | D18: 6.89 | E18: 6.97 | F18: 5.86 | G18: 6.6 | H18: 6.49 | I18: 6.78 | J18: 5.67
A19: QT_100 | B19: kg/l | C19: 1.069 | D19: 1.065 | E19: 1.053 | F19: 1.057 | G19: 1.069 | H19: 1.075 | I19: 1.071 | J19: 1.059
A20: QT_101 | B20: kg/l | C20: 1.091 | D20: 1.097 | E20: 1.102 | F20: 1.097 | G20: 1.092 | H20: 1.102 | I20: 1.096 | J20: 1.073
... A51: TV5 | B51: °C | C51: 43.26 | D51: 50.54 | E51: 49.37 | F51: 43.55 | G51: 47.16 | H51: 40.71 | I51: 41.86 | J51: 37.87
A52: Test | C52: 10 | D52: 55

Sheet SS case 1
A1: Timeline: | B1: Engineering
A2: Model server: | B2: ProcessModel
A4: Case: | B4: 1
A6: Fargevisning:
A7: Grønn: | B7: 0 | C7: 5
A8: Gul: | B8: 5 | C8: 10
A9: Rød: | B9: 10 | C9: 100
A11: TAG in literature | B11: Value from Appendix A | C11: TAG in model | D11: Data-tag in model | E11: SimulatedValue | F11: unit | G11: % deviation | H11: Comment
A12: SETPOINTS SET IN MCL
A13: FT06 | B13: =IFERROR(_xlfn.XLOOKUP(A13,'Appendix A'!A:A,'Appendix A'!C:C),"") -> 89.77 | C13: 00FIC001 | D13: 00FIC001:InternalSetpoint | E13: {=_xll.ReadKSpice(_xlfn.CONCAT("/",$B$1,"/",$B$2,"/",D13,"@V_Unit=",F13))} -> #N/A | F13: m3/h | G13: =100*(E13-B13)/B13 -> #N/A | H13: Gas Flow Rate
A14: FT_100 | B14: =IFERROR(_xlfn.XLOOKUP(A14,'Appendix A'!A:A,'Appendix A'!C:C),"") -> 166.93 | C14: 00FC001 | D14: 00FC001:InternalSetpoint | E14: {=_xll.ReadKSpice(_xlfn.CONCAT("/",$B$1,"/",$B$2,"/",D14,"@V_Unit=",F14))} -> #N/A | F14: kg/h | G14: =100*(E14-B14)/B14 -> #N/A | H14: Solvent Flow Rate Lean input
A15: PI_103 | B15: =IFERROR(_xlfn.XLOOKUP(A15,'Appendix A'!A:A,'Appendix A'!C:C),"") -> 1016.6 | C15: 00PIC001 | D15: 00PIC001:InternalSetpoint | E15: {=_xll.ReadKSpice(_xlfn.CONCAT("/",$B$1,"/",$B$2,"/",D15,"@V_Unit=",F15))} -> #N/A | F15: mbara | G15: =100*(E15-B15)/B15 -> #N/A | H15: Pressure of flue gas boundry
A16: TA08 | B16: =IFERROR(_xlfn.XLOOKUP(A16,'Appendix A'!A:A,'Appendix A'!C:C),"") -> 49.1 | C16: LeanMEA_inn | D16: LeanMEA_inn:InstructorTemperature | E16: {=_xll.ReadKSpice(_xlfn.CONCAT("/",$B$1,"/",$B$2,"/",D16,"@V_Unit=",F16))} -> #N/A | F16: degC | G16: =100*(E16-B16)/B16 -> #N/A | H16: Temperature Lean Solvent LeanMEA_inn
A17: TA08 | B17: =IFERROR(_xlfn.XLOOKUP(A17,'Appendix A'!A:A,'Appendix A'!C:C),"") -> 49.1 | C17: 02TIC002 | D17: 02TIC002:InternalSetpoint | E17: {=_xll.ReadKSpice(_xlfn.CONCAT("/",$B$1,"/",$B$2,"/",D17,"@V_Unit=",F17))} -> #N/A | F17: degC | G17: =100*(E17-B17)/B17 -> #N/A | H17: Temperature Lean Solvent LeanMEA_ut
A18: HE_04/05/06 | B18: =IFERROR(_xlfn.XLOOKUP(A18,'Appendix A'!A:A,'Appendix A'!C:C),"") -> 6.82 | C18: 02QIC001 | D18: 02QIC001:InternalSetpoint | E18: {=_xll.ReadKSpice(_xlfn.CONCAT("/",$B$1,"/",$B$2,"/",D18,"@V_Unit=",F18))} -> #N/A | F18: kW | G18: =100*(E18-B18)/B18 -> #N/A | H18: Reboiler Duty
A19: TAB | B19: =IFERROR(_xlfn.XLOOKUP(A19,'Appendix A'!A:A,'Appendix A'!C:C),"") -> 42.18 | C19: 00TIC000 | D19: 00TIC000:InternalSetpoint | E19: {=_xll.ReadKSpice(_xlfn.CONCAT("/",$B$1,"/",$B$2,"/",D19,"@V_Unit=",F19))} -> #N/A | F19: degC | G19: =100*(E19-B19)/B19 -> #N/A | H19: Absorber Inlet CO2 Temperature
B20: 0.3 | C20: LAL_IN | D20: LAL_IN:Output | E20: {=_xll.ReadKSpice(_xlfn.CONCAT("/",$B$1,"/",$B$2,"/",D20,"@V_Unit=",F20))} -> #N/A | F20: mol/mol | G20: =100*(E20-B20)/B20 -> #N/A | H20: CO2 Loading Lean input
A21: PI_100 | B21: =IFERROR(_xlfn.XLOOKUP(A21,'Appendix A'!A:A,'Appendix A'!C:C),"") -> 1014.07 | C21: 00PIC002 | D21: 00PIC002:InternalSetpoint | E21: {=_xll.ReadKSpice(_xlfn.CONCAT("/",$B$1,"/",$B$2,"/",D21,"@V_Unit=",F21))} -> #N/A | F21: mbara | G21: =100*(E21-B21)/B21 -> #N/A | H21: Pressure in absorber
A22: PT_02 | B22: =IFERROR(_xlfn.XLOOKUP(A22,'Appendix A'!A:A,'Appendix A'!C:C),"") -> 0.9 | C22: 04PIC001 | D22: 04PIC001:InternalSetpoint | E22: {=_xll.ReadKSpice(_xlfn.CONCAT("/",$B$1,"/",$B$2,"/",D22,"@V_Unit=",F22))} -> #N/A | F22: barg | G22: =100*(E22-B22)/B22 -> #N/A | H22: Pressure in reboiler
A23: TT_01 | B23: =IFERROR(_xlfn.XLOOKUP(A23,'Appendix A'!A:A,'Appendix A'!C:C),"") -> 30.65 | C23: 03TIC001 | D23: 03TIC001:InternalSetpoint | E23: {=_xll.ReadKSpice(_xlfn.CONCAT("/",$B$1,"/",$B$2,"/",D23,"@V_Unit=",F23))} -> #N/A | F23: degC | G23: =100*(E23-B23)/B23 -> #N/A | H23: EX03 cooling loop
A24: TT_02 | B24: =IFERROR(_xlfn.XLOOKUP(A24,'Appendix A'!A:A,'Appendix A'!C:C),"") -> 18.08 | C24: 04TIC001 | D24: 04TIC001:InternalSetpoint | E24: {=_xll.ReadKSpice(_xlfn.CONCAT("/",$B$1,"/",$B$2,"/",D24,"@V_Unit=",F24))} -> #N/A | F24: degC | G24: =100*(E24-B24)/B24 -> #N/A | H24: EX04 cooling loop
A26: FLOW INTO ABSORBER
A27: FT06 | B27: =IFERROR(_xlfn.XLOOKUP(A27,'Appendix A'!A:A,'Appendix A'!C:C),"") -> 89.77 | C27: 00FT001 | D27: 00FT001:MeasuredValue | E27: {=_xll.ReadKSpice(_xlfn.CONCAT("/",$B$1,"/",$B$2,"/",D27,"@V_Unit=",F27))} -> #N/A | F27: m3/h | G27: =100*(E27-B27)/B27 -> #N/A
A28: PI_103 | B28: =IFERROR(_xlfn.XLOOKUP(A28,'Appendix A'!A:A,'Appendix A'!C:C),"") -> 1016.6 | C28: 00PT001 | D28: 00PT001:MeasuredValue | E28: {=_xll.ReadKSpice(_xlfn.CONCAT("/",$B$1,"/",$B$2,"/",D28,"@V_Unit=",F28))} -> #N/A | F28: mbara | G28: =100*(E28-B28)/B28 -> #N/A
A29: TV5 | B29: =IFERROR(_xlfn.XLOOKUP(A29,'Appendix A'!A:A,'Appendix A'!C:C),"") -> 43.26 | C29: 00TAB000 | D29: 00TAB000:MeasuredValue | E29: {=_xll.ReadKSpice(_xlfn.CONCAT("/",$B$1,"/",$B$2,"/",D29,"@V_Unit=",F29))} -> #N/A | F29: degC | G29: =100*(E29-B29)/B29 -> #N/A
A30: FT_100 | B30: =IFERROR(_xlfn.XLOOKUP(A30,'Appendix A'!A:A,'Appendix A'!C:C),"") -> 166.93 | C30: 00FT003 | D30: 00FT003:MeasuredValue | E30: {=_xll.ReadKSpice(_xlfn.CONCAT("/",$B$1,"/",$B$2,"/",D30,"@V_Unit=",F30))} -> #N/A | F30: kg/h | G30: =100*(E30-B30)/B30 -> #N/A
A31: TA08 | B31: =IFERROR(_xlfn.XLOOKUP(A31,'Appendix A'!A:A,'Appendix A'!C:C),"") -> 49.1 | C31: LeanAmineInput | D31: LeanAmineInput:OutletStream.t | E31: {=_xll.ReadKSpice(_xlfn.CONCAT("/",$B$1,"/",$B$2,"/",D31,"@V_Unit=",F31))} -> #N/A | F31: degC | G31: =100*(E31-B31)/B31 -> #N/A | H31: Temperature Lean Solvent LeanMEA_inn
A32: TA08 | B32: =IFERROR(_xlfn.XLOOKUP(A32,'Appendix A'!A:A,'Appendix A'!C:C),"") -> 49.1 | C32: 02TT002 | D32: 02TT002:MeasuredValue | E32: {=_xll.ReadKSpice(_xlfn.CONCAT("/",$B$1,"/",$B$2,"/",D32,"@V_Unit=",F32))} -> #N/A | F32: degC | G32: =100*(E32-B32)/B32 -> #N/A | H32: Temperature Lean Solvent LeanMEA_ut
A34: ABSORBER
A35: CO2_IN | B35: =IFERROR(_xlfn.XLOOKUP(A35,'Appendix A'!A:A,'Appendix A'!C:C),"") -> 3.52 | C35: GasToAbsorber | D35: GasToAbsorber:OutputCompositionVector[4] | E35: {=_xll.ReadKSpice(_xlfn.CONCAT("/",$B$1,"/",$B$2,"/",D35,"@V_Unit=",F35))} -> #N/A | F35: % | G35: =100*(E35-B35)/B35 -> #N/A | H35: % CO2
A36: CO2_OUT (Gas) | B36: =IFERROR(_xlfn.XLOOKUP(A36,'Appendix A'!A:A,'Appendix A'!D:D),"") | C36: GasFromAbsorber | D36: GasFromAbsorber:OutputCompositionVector[4] | E36: {=_xll.ReadKSpice(_xlfn.CONCAT("/",$B$1,"/",$B$2,"/",D36,"@V_Unit=",F36))} -> #N/A | F36: % | H36: CO2 in gas form
A37: CO2_OUT (In MEA) | B37: =IFERROR(_xlfn.XLOOKUP(A37,'Appendix A'!A:A,'Appendix A'!D:D),"") | C37: GasFromAbsorber | D37: GasFromAbsorber:OutputCompositionVector[2] | E37: {=_xll.ReadKSpice(_xlfn.CONCAT("/",$B$1,"/",$B$2,"/",D37,"@V_Unit=",F37))} -> #N/A | F37: % | H37: CO2 in MEA
A38: CO2_OUT | B38: =IFERROR(_xlfn.XLOOKUP(A38,'Appendix A'!A:A,'Appendix A'!C:C),"") -> 0.29 | C38: GasFromAbsorber | E38: =E37+E36 -> #N/A | F38: % | G38: =100*(E38-B38)/B38 -> #N/A | H38: Combined CO2 % in treated gas
A39: PI_100 | B39: =IFERROR(_xlfn.XLOOKUP(A39,'Appendix A'!A:A,'Appendix A'!C:C),"") -> 1014.07 | C39: 00PI100 | D39: 00PI100:MeasuredValue | E39: {=_xll.ReadKSpice(_xlfn.CONCAT("/",$B$1,"/",$B$2,"/",D39,"@V_Unit=",F39))} -> #N/A | F39: mbara | G39: =100*(E39-B39)/B39 -> #N/A
A40: PI_102 | B40: =IFERROR(_xlfn.XLOOKUP(A40,'Appendix A'!A:A,'Appendix A'!C:C),"") -> 1019.19 | C40: 00PI102 | D40: 00PI102:MeasuredValue | E40: {=_xll.ReadKSpice(_xlfn.CONCAT("/",$B$1,"/",$B$2,"/",D40,"@V_Unit=",F40))} -> #N/A | F40: mbara | G40: =100*(E40-B40)/B40 -> #N/A
A41: TAB | B41: =IFERROR(_xlfn.XLOOKUP(A41,'Appendix A'!A:A,'Appendix A'!C:C),"") -> 42.18 | C41: 00TAB000 | D41: 00TAB000:MeasuredValue | E41: {=_xll.ReadKSpice(_xlfn.CONCAT("/",$B$1,"/",$B$2,"/",D41,"@V_Unit=",F41))} -> #N/A | F41: degC | G41: =100*(E41-B41)/B41 -> #N/A | H41: Lik TV5? Det er samme transpimmer i K-spice
A42: TA00 | B42: =IFERROR(_xlfn.XLOOKUP(A42,'Appendix A'!A:A,'Appendix A'!C:C),"") -> 45.14 | C42: 00TA000 | D42: 00TA000:MeasuredValue | E42: {=_xll.ReadKSpice(_xlfn.CONCAT("/",$B$1,"/",$B$2,"/",D42,"@V_Unit=",F42))} -> #N/A | F42: degC | G42: =100*(E42-B42)/B42 -> #N/A
A43: TA01 | B43: =IFERROR(_xlfn.XLOOKUP(A43,'Appendix A'!A:A,'Appendix A'!C:C),"") -> 46.62 | C43: 00TA001 | D43: 00TA001:MeasuredValue | E43: {=_xll.ReadKSpice(_xlfn.CONCAT("/",$B$1,"/",$B$2,"/",D43,"@V_Unit=",F43))} -> #N/A | F43: degC | G43: =100*(E43-B43)/B43 -> #N/A
A44: TA02 | B44: =IFERROR(_xlfn.XLOOKUP(A44,'Appendix A'!A:A,'Appendix A'!C:C),"") -> 49.38 | C44: 00TA002 | D44: 00TA002:MeasuredValue | E44: {=_xll.ReadKSpice(_xlfn.CONCAT("/",$B$1,"/",$B$2,"/",D44,"@V_Unit=",F44))} -> #N/A | F44: degC | G44: =100*(E44-B44)/B44 -> #N/A
A45: TA03 | B45: =IFERROR(_xlfn.XLOOKUP(A45,'Appendix A'!A:A,'Appendix A'!C:C),"") -> 50.97 | C45: 00TA003 | D45: 00TA003:MeasuredValue | E45: {=_xll.ReadKSpice(_xlfn.CONCAT("/",$B$1,"/",$B$2,"/",D45,"@V_Unit=",F45))} -> #N/A | F45: degC | G45: =100*(E45-B45)/B45 -> #N/A
...

Sheet SS case 1 (v19.7_CL)
A1: Timeline: | B1: Engineering
A2: Model server: | B2: ProcessModel
A4: Case: | B4: 1
A6: Fargevisning:
A7: Grønn: | B7: 0 | C7: 5
A8: Gul: | B8: 5 | C8: 10
A9: Rød: | B9: 10 | C9: 100
A11: TAG in literature | B11: Value from Appendix A | C11: TAG in model | D11: Data-tag in model | E11: SimulatedValue | F11: unit | G11: % deviation | H11: Comment
A12: SETPOINTS SET IN MCL
A13: FT06 | B13: 89.77 | C13: 00FIC001 | D13: 00FIC001:InternalSetpoint | E13: 89.77 | F13: m3/h | G13: 0 | H13: Gas Flow Rate
A14: FT_100 | B14: 166.93 | C14: 00FC001 | D14: 00FC001:InternalSetpoint | E14: 166.9 | F14: kg/h | G14: -0.017971605 | H14: Solvent Flow Rate Lean input
A15: PI_103 | B15: 1016.6 | C15: 00PIC001 | D15: 00PIC001:InternalSetpoint | E15: 1016.6 | F15: mbara | G15: 0 | H15: Pressure of flue gas boundry
A16: TA08 | B16: 49.1 | C16: LeanMEA_inn | D16: LeanMEA_inn:InstructorTemperature | E16: 49.1 | F16: degC | G16: 4.3414016e-14 | H16: Temperature Lean Solvent LeanMEA_inn
A17: TA08 | B17: 49.1 | C17: 02TIC002 | D17: 02TIC002:InternalSetpoint | E17: 49.1 | F17: degC | G17: 4.3414016e-14 | H17: Temperature Lean Solvent LeanMEA_ut
A18: HE_04/05/06 | B18: 6.82 | C18: 02QIC001 | D18: 02QIC001:InternalSetpoint | E18: 6.8 | F18: kW | G18: -0.29325513 | H18: Reboiler Duty
A19: TAB | B19: 42.18 | C19: 00TIC000 | D19: 00TIC000:InternalSetpoint | E19: 42.18 | F19: degC | G19: 1.6845489e-14 | H19: Absorber Inlet CO2 Temperature
B20: 0.3 | C20: LAL_IN | D20: LAL_IN:Output | E20: 0.29999017 | F20: mol/mol | G20: -0.0032759566 | H20: CO2 Loading Lean input
A21: PI_100 | B21: 1014.07 | C21: 00PIC002 | D21: 00PIC002:InternalSetpoint | E21: 1014.07 | F21: mbara | G21: 0 | H21: Pressure in absorber
A22: PT_02 | B22: 0.9 | C22: 04PIC001 | D22: 04PIC001:InternalSetpoint | E22: 0.9 | F22: barg | G22: 1.2335811e-14 | H22: Pressure in reboiler
A23: TT_01 | B23: 30.65 | C23: 03TIC001 | D23: 03TIC001:InternalSetpoint | E23: 30.65 | F23: degC | G23: -6.9547413e-14 | H23: EX03 cooling loop
A24: TT_02 | B24: 18.08 | C24: 04TIC001 | D24: 04TIC001:InternalSetpoint | E24: 18.08 | F24: degC | G24: -7.859986e-14 | H24: EX04 cooling loop
A26: FLOW INTO ABSORBER
A27: FT06 | B27: 89.77 | C27: 00FT001 | D27: 00FT001:MeasuredValue | E27: 94.060759 | F27: m3/h | G27: 4.7797249
A28: PI_103 | B28: 1016.6 | C28: 00PT001 | D28: 00PT001:MeasuredValue | E28: 1016.7226 | F28: mbara | G28: 0.012059023
A29: TV5 | B29: 43.26 | C29: 00TAB000 | D29: 00TAB000:MeasuredValue | E29: 42.778232 | F29: degC | G29: -1.113658
A30: FT_100 | B30: 166.93 | C30: 00FT003 | D30: 00FT003:MeasuredValue | E30: 166.88021 | F30: kg/h | G30: -0.029825566
A31: TA08 | B31: 49.1 | C31: LeanAmineInput | D31: LeanAmineInput:OutletStream.t | E31: 49.105505 | F31: degC | G31: 0.011212742 | H31: Temperature Lean Solvent LeanMEA_inn
A32: TA08 | B32: 49.1 | C32: 02TT002 | D32: 02TT002:MeasuredValue | E32: 39.371812 | F32: degC | G32: -19.813011 | H32: Temperature Lean Solvent LeanMEA_ut
A34: ABSORBER
A35: CO2_IN | B35: 3.52 | C35: GasToAbsorber | D35: GasToAbsorber:OutputCompositionVector[4] | E35: 3.5 | F35: % | G35: -0.56818182 | H35: % CO2
A36: CO2_OUT (Gas) | C36: GasFromAbsorber | D36: GasFromAbsorber:OutputCompositionVector[4] | E36: 0.12271817 | F36: % | H36: CO2 in gas form
A37: CO2_OUT (In MEA) | C37: GasFromAbsorber | D37: GasFromAbsorber:OutputCompositionVector[2] | E37: 0.066474997 | F37: % | H37: CO2 in MEA
A38: CO2_OUT | B38: 0.29 | C38: GasFromAbsorber | E38: 0.18919316 | F38: % | G38: -34.760978 | H38: Combined CO2 % in treated gas
A39: PI_100 | B39: 1014.07 | C39: 00PI100 | D39: 00PI100:MeasuredValue | E39: 1013.7902 | F39: mbara | G39: -0.027591504
A40: PI_102 | B40: 1019.19 | C40: 00PI102 | D40: 00PI102:MeasuredValue | E40: 1016.5847 | F40: mbara | G40: -0.25562579
A41: TAB | B41: 42.18 | C41: 00TAB000 | D41: 00TAB000:MeasuredValue | E41: 42.778232 | F41: degC | G41: 1.4182825 | H41: Lik TV5? Det er samme transpimmer i K-spice
A42: TA00 | B42: 45.14 | C42: 00TA000 | D42: 00TA000:MeasuredValue | E42: 41.340293 | F42: degC | G42: -8.4176058
A43: TA01 | B43: 46.62 | C43: 00TA001 | D43: 00TA001:MeasuredValue | E43: 44.256293 | F43: degC | G43: -5.0701561
A44: TA02 | B44: 49.38 | C44: 00TA002 | D44: 00TA002:MeasuredValue | E44: 51.046223 | F44: degC | G44: 3.3742867
A45: TA03 | B45: 50.97 | C45: 00TA003 | D45: 00TA003:MeasuredValue | E45: 51.32473 | F45: degC | G45: 0.69595826
...

Sheet SS case 2
A1: Timeline: | B1: Engineering
A2: Model server: | B2: ProcessModel
A4: Case: | B4: 2
A6: Fargevisning:
A7: Grønn: | B7: 0 | C7: 5
A8: Gul: | B8: 5 | C8: 10
A9: Rød: | B9: 10 | C9: 100
A11: TAG in literature | B11: Value from Appendix A | C11: TAG in model | D11: Data-tag in model | E11: SimulatedValue | F11: unit | G11: % deviation | H11: Comment
A12: SETPOINTS SET IN MCL
A13: FT06 | B13: =IFERROR(_xlfn.XLOOKUP(A13,'Appendix A'!A:A,'Appendix A'!D:D),"") -> 90.09 | C13: 00FIC001 | D13: 00FIC001:InternalSetpoint | E13: {=_xll.ReadKSpice(_xlfn.CONCAT("/",$B$1,"/",$B$2,"/",D13,"@V_Unit=",F13))} -> #N/A | F13: m3/h | G13: =100*(E13-B13)/B13 -> #N/A | H13: Gas Flow Rate
A14: FT_100 | B14: =IFERROR(_xlfn.XLOOKUP(A14,'Appendix A'!A:A,'Appendix A'!D:D),"") -> 172.33 | C14: 00FC001 | D14: 00FC001:InternalSetpoint | E14: {=_xll.ReadKSpice(_xlfn.CONCAT("/",$B$1,"/",$B$2,"/",D14,"@V_Unit=",F14))} -> #N/A | F14: kg/h | G14: =100*(E14-B14)/B14 -> #N/A | H14: Solvent Flow Rate Lean input
A15: PI_103 | B15: =IFERROR(_xlfn.XLOOKUP(A15,'Appendix A'!A:A,'Appendix A'!D:D),"") -> 1010.37 | C15: 00PIC001 | D15: 00PIC001:InternalSetpoint | E15: {=_xll.ReadKSpice(_xlfn.CONCAT("/",$B$1,"/",$B$2,"/",D15,"@V_Unit=",F15))} -> #N/A | F15: mbara | G15: =100*(E15-B15)/B15 -> #N/A | H15: Pressure of flue gas boundry
A16: TA08 | B16: =IFERROR(_xlfn.XLOOKUP(A16,'Appendix A'!A:A,'Appendix A'!D:D),"") -> 58.31 | C16: LeanMEA_inn | D16: LeanMEA_inn:InstructorTemperature | E16: {=_xll.ReadKSpice(_xlfn.CONCAT("/",$B$1,"/",$B$2,"/",D16,"@V_Unit=",F16))} -> #N/A | F16: degC | G16: =100*(E16-B16)/B16 -> #N/A | H16: Temperature Lean Solvent LeanMEA_inn
A17: TA08 | B17: =IFERROR(_xlfn.XLOOKUP(A17,'Appendix A'!A:A,'Appendix A'!D:D),"") -> 58.31 | C17: 02TIC002 | D17: 02TIC002:InternalSetpoint | E17: {=_xll.ReadKSpice(_xlfn.CONCAT("/",$B$1,"/",$B$2,"/",D17,"@V_Unit=",F17))} -> #N/A | F17: degC | G17: =100*(E17-B17)/B17 -> #N/A | H17: Temperature Lean Solvent LeanMEA_ut
A18: HE_04/05/06 | B18: =IFERROR(_xlfn.XLOOKUP(A18,'Appendix A'!A:A,'Appendix A'!D:D),"") -> 9.23 | C18: 02QIC001 | D18: 02QIC001:InternalSetpoint | E18: {=_xll.ReadKSpice(_xlfn.CONCAT("/",$B$1,"/",$B$2,"/",D18,"@V_Unit=",F18))} -> #N/A | F18: kW | G18: =100*(E18-B18)/B18 -> #N/A | H18: Reboiler Duty
A19: TAB | B19: =IFERROR(_xlfn.XLOOKUP(A19,'Appendix A'!A:A,'Appendix A'!D:D),"") -> 49.24 | C19: 00TIC000 | D19: 00TIC000:InternalSetpoint | E19: {=_xll.ReadKSpice(_xlfn.CONCAT("/",$B$1,"/",$B$2,"/",D19,"@V_Unit=",F19))} -> #N/A | F19: degC | G19: =100*(E19-B19)/B19 -> #N/A | H19: Absorber Inlet CO2 Temperature
B20: 0.26 | C20: LAL_IN | D20: LAL_IN:Output | E20: {=_xll.ReadKSpice(_xlfn.CONCAT("/",$B$1,"/",$B$2,"/",D20,"@V_Unit=",F20))} -> #N/A | F20: mol/mol | G20: =100*(E20-B20)/B20 -> #N/A | H20: CO2 Loading Lean input
A21: PI_100 | B21: =IFERROR(_xlfn.XLOOKUP(A21,'Appendix A'!A:A,'Appendix A'!D:D),"") -> 1002.74 | C21: 00PIC002 | D21: 00PIC002:InternalSetpoint | E21: {=_xll.ReadKSpice(_xlfn.CONCAT("/",$B$1,"/",$B$2,"/",D21,"@V_Unit=",F21))} -> #N/A | F21: mbara | G21: =100*(E21-B21)/B21 -> #N/A | H21: Pressure in absorber
A22: PT_02 | B22: =IFERROR(_xlfn.XLOOKUP(A22,'Appendix A'!A:A,'Appendix A'!D:D),"") -> 0.9 | C22: 04PIC001 | D22: 04PIC001:InternalSetpoint | E22: {=_xll.ReadKSpice(_xlfn.CONCAT("/",$B$1,"/",$B$2,"/",D22,"@V_Unit=",F22))} -> #N/A | F22: barg | G22: =100*(E22-B22)/B22 -> #N/A | H22: Pressure in reboiler
A23: TT_01 | B23: =IFERROR(_xlfn.XLOOKUP(A23,'Appendix A'!A:A,'Appendix A'!D:D),"") -> 30.64 | C23: 03TIC001 | D23: 03TIC001:InternalSetpoint | E23: {=_xll.ReadKSpice(_xlfn.CONCAT("/",$B$1,"/",$B$2,"/",D23,"@V_Unit=",F23))} -> #N/A | F23: degC | G23: =100*(E23-B23)/B23 -> #N/A | H23: EX03 cooling loop
A24: TT_02 | B24: =IFERROR(_xlfn.XLOOKUP(A24,'Appendix A'!A:A,'Appendix A'!D:D),"") -> 25.01 | C24: 04TIC001 | D24: 04TIC001:InternalSetpoint | E24: {=_xll.ReadKSpice(_xlfn.CONCAT("/",$B$1,"/",$B$2,"/",D24,"@V_Unit=",F24))} -> #N/A | F24: degC | G24: =100*(E24-B24)/B24 -> #N/A | H24: EX04 cooling loop
A26: FLOW INTO ABSORBER
A27: FT06 | B27: =IFERROR(_xlfn.XLOOKUP(A27,'Appendix A'!A:A,'Appendix A'!D:D),"") -> 90.09 | C27: 00FT001 | D27: 00FT001:MeasuredValue | E27: {=_xll.ReadKSpice(_xlfn.CONCAT("/",$B$1,"/",$B$2,"/",D27,"@V_Unit=",F27))} -> #N/A | F27: m3/h | G27: =100*(E27-B27)/B27 -> #N/A
A28: PI_103 | B28: =IFERROR(_xlfn.XLOOKUP(A28,'Appendix A'!A:A,'Appendix A'!D:D),"") -> 1010.37 | C28: 00PT001 | D28: 00PT001:MeasuredValue | E28: {=_xll.ReadKSpice(_xlfn.CONCAT("/",$B$1,"/",$B$2,"/",D28,"@V_Unit=",F28))} -> #N/A | F28: mbara | G28: =100*(E28-B28)/B28 -> #N/A
A29: TV5 | B29: =IFERROR(_xlfn.XLOOKUP(A29,'Appendix A'!A:A,'Appendix A'!D:D),"") -> 50.54 | C29: 00TAB000 | D29: 00TAB000:MeasuredValue | E29: {=_xll.ReadKSpice(_xlfn.CONCAT("/",$B$1,"/",$B$2,"/",D29,"@V_Unit=",F29))} -> #N/A | F29: degC | G29: =100*(E29-B29)/B29 -> #N/A
A30: FT_100 | B30: =IFERROR(_xlfn.XLOOKUP(A30,'Appendix A'!A:A,'Appendix A'!D:D),"") -> 172.33 | C30: 00FT003 | D30: 00FT003:MeasuredValue | E30: {=_xll.ReadKSpice(_xlfn.CONCAT("/",$B$1,"/",$B$2,"/",D30,"@V_Unit=",F30))} -> #N/A | F30: kg/h | G30: =100*(E30-B30)/B30 -> #N/A
A31: TA08 | B31: =IFERROR(_xlfn.XLOOKUP(A31,'Appendix A'!A:A,'Appendix A'!D:D),"") -> 58.31 | C31: LeanAmineInput | D31: LeanAmineInput:OutletStream.t | E31: {=_xll.ReadKSpice(_xlfn.CONCAT("/",$B$1,"/",$B$2,"/",D31,"@V_Unit=",F31))} -> #N/A | F31: degC | G31: =100*(E31-B31)/B31 -> #N/A | H31: Temperature Lean Solvent LeanMEA_inn
A32: TA08 | B32: =IFERROR(_xlfn.XLOOKUP(A32,'Appendix A'!A:A,'Appendix A'!D:D),"") -> 58.31 | C32: 02TT002 | D32: 02TT002:MeasuredValue | E32: {=_xll.ReadKSpice(_xlfn.CONCAT("/",$B$1,"/",$B$2,"/",D32,"@V_Unit=",F32))} -> #N/A | F32: degC | G32: =100*(E32-B32)/B32 -> #N/A | H32: Temperature Lean Solvent LeanMEA_ut
A34: ABSORBER
A35: CO2_IN | B35: =IFERROR(_xlfn.XLOOKUP(A35,'Appendix A'!A:A,'Appendix A'!D:D),"") -> 6.77 | C35: GasToAbsorber | D35: GasToAbsorber:OutputCompositionVector[4] | E35: {=_xll.ReadKSpice(_xlfn.CONCAT("/",$B$1,"/",$B$2,"/",D35,"@V_Unit=",F35))} -> #N/A | F35: % | G35: =100*(E35-B35)/B35 -> #N/A | H35: % CO2
A36: CO2_OUT (Gas) | B36: =IFERROR(_xlfn.XLOOKUP(A36,'Appendix A'!A:A,'Appendix A'!D:D),"") | C36: GasFromAbsorber | D36: GasFromAbsorber:OutputCompositionVector[4] | E36: {=_xll.ReadKSpice(_xlfn.CONCAT("/",$B$1,"/",$B$2,"/",D36,"@V_Unit=",F36))} -> #N/A | F36: % | H36: CO2 in gas form
A37: CO2_OUT (In MEA) | B37: =IFERROR(_xlfn.XLOOKUP(A37,'Appendix A'!A:A,'Appendix A'!D:D),"") | C37: GasFromAbsorber | D37: GasFromAbsorber:OutputCompositionVector[2] | E37: {=_xll.ReadKSpice(_xlfn.CONCAT("/",$B$1,"/",$B$2,"/",D37,"@V_Unit=",F37))} -> #N/A | F37: % | H37: CO2 in MEA
A38: CO2_OUT | B38: =IFERROR(_xlfn.XLOOKUP(A38,'Appendix A'!A:A,'Appendix A'!D:D),"") -> 1.19 | C38: GasFromAbsorber | E38: =E37+E36 -> #N/A | F38: % | G38: =100*(E38-B38)/B38 -> #N/A | H38: Combined CO2 % in treated gas
A39: PI_100 | B39: =IFERROR(_xlfn.XLOOKUP(A39,'Appendix A'!A:A,'Appendix A'!D:D),"") -> 1002.74 | C39: 00PI100 | D39: 00PI100:MeasuredValue | E39: {=_xll.ReadKSpice(_xlfn.CONCAT("/",$B$1,"/",$B$2,"/",D39,"@V_Unit=",F39))} -> #N/A | F39: mbara | G39: =100*(E39-B39)/B39 -> #N/A
A40: PI_102 | B40: =IFERROR(_xlfn.XLOOKUP(A40,'Appendix A'!A:A,'Appendix A'!D:D),"") -> 1005.78 | C40: 00PI102 | D40: 00PI102:MeasuredValue | E40: {=_xll.ReadKSpice(_xlfn.CONCAT("/",$B$1,"/",$B$2,"/",D40,"@V_Unit=",F40))} -> #N/A | F40: mbara | G40: =100*(E40-B40)/B40 -> #N/A
A41: TAB | B41: =IFERROR(_xlfn.XLOOKUP(A41,'Appendix A'!A:A,'Appendix A'!D:D),"") -> 49.24 | C41: 00TAB000 | D41: 00TAB000:MeasuredValue | E41: {=_xll.ReadKSpice(_xlfn.CONCAT("/",$B$1,"/",$B$2,"/",D41,"@V_Unit=",F41))} -> #N/A | F41: degC | G41: =100*(E41-B41)/B41 -> #N/A | H41: Lik TV5? Det er samme transpimmer i K-spice
A42: TA00 | B42: =IFERROR(_xlfn.XLOOKUP(A42,'Appendix A'!A:A,'Appendix A'!D:D),"") -> 51.61 | C42: 00TA000 | D42: 00TA000:MeasuredValue | E42: {=_xll.ReadKSpice(_xlfn.CONCAT("/",$B$1,"/",$B$2,"/",D42,"@V_Unit=",F42))} -> #N/A | F42: degC | G42: =100*(E42-B42)/B42 -> #N/A
A43: TA01 | B43: =IFERROR(_xlfn.XLOOKUP(A43,'Appendix A'!A:A,'Appendix A'!D:D),"") -> 52.68 | C43: 00TA001 | D43: 00TA001:MeasuredValue | E43: {=_xll.ReadKSpice(_xlfn.CONCAT("/",$B$1,"/",$B$2,"/",D43,"@V_Unit=",F43))} -> #N/A | F43: degC | G43: =100*(E43-B43)/B43 -> #N/A
A44: TA02 | B44: =IFERROR(_xlfn.XLOOKUP(A44,'Appendix A'!A:A,'Appendix A'!D:D),"") -> 53.57 | C44: 00TA002 | D44: 00TA002:MeasuredValue | E44: {=_xll.ReadKSpice(_xlfn.CONCAT("/",$B$1,"/",$B$2,"/",D44,"@V_Unit=",F44))} -> #N/A | F44: degC | G44: =100*(E44-B44)/B44 -> #N/A
A45: TA03 | B45: =IFERROR(_xlfn.XLOOKUP(A45,'Appendix A'!A:A,'Appendix A'!D:D),"") -> 54.13 | C45: 00TA003 | D45: 00TA003:MeasuredValue | E45: {=_xll.ReadKSpice(_xlfn.CONCAT("/",$B$1,"/",$B$2,"/",D45,"@V_Unit=",F45))} -> #N/A | F45: degC | G45: =100*(E45-B45)/B45 -> #N/A
...

Sheet SS case 3
A1: Timeline: | B1: Engineering
A2: Model server: | B2: ProcessModel
A4: Case: | B4: 3
A6: Fargevisning:
A7: Grønn: | B7: 0 | C7: 5
A8: Gul: | B8: 5 | C8: 10
A9: Rød: | B9: 10 | C9: 100
A11: TAG in literature | B11: Value from Appendix A | C11: TAG in model | D11: Data-tag in model | E11: SimulatedValue | F11: unit | G11: % deviation | H11: Comment
A12: SETPOINTS SET IN MCL
A13: FT06 | B13: =IFERROR(_xlfn.XLOOKUP(A13,'Appendix A'!A:A,'Appendix A'!E:E),"") -> 127.02 | C13: 00FIC001 | D13: 00FIC001:InternalSetpoint | E13: {=_xll.ReadKSpice(_xlfn.CONCAT("/",$B$1,"/",$B$2,"/",D13,"@V_Unit=",F13))} -> #N/A | F13: m3/h | G13: =100*(E13-B13)/B13 -> #N/A | H13: Gas Flow Rate
A14: FT_100 | B14: =IFERROR(_xlfn.XLOOKUP(A14,'Appendix A'!A:A,'Appendix A'!E:E),"") -> 152.07 | C14: 00FC001 | D14: 00FC001:InternalSetpoint | E14: {=_xll.ReadKSpice(_xlfn.CONCAT("/",$B$1,"/",$B$2,"/",D14,"@V_Unit=",F14))} -> #N/A | F14: kg/h | G14: =100*(E14-B14)/B14 -> #N/A | H14: Solvent Flow Rate Lean input
A15: PI_103 | B15: =IFERROR(_xlfn.XLOOKUP(A15,'Appendix A'!A:A,'Appendix A'!E:E),"") -> 1056.4 | C15: 00PIC001 | D15: 00PIC001:InternalSetpoint | E15: {=_xll.ReadKSpice(_xlfn.CONCAT("/",$B$1,"/",$B$2,"/",D15,"@V_Unit=",F15))} -> #N/A | F15: mbara | G15: =100*(E15-B15)/B15 -> #N/A | H15: Pressure of flue gas boundry
A16: TA08 | B16: =IFERROR(_xlfn.XLOOKUP(A16,'Appendix A'!A:A,'Appendix A'!E:E),"") -> 57.95 | C16: LeanMEA_inn | D16: LeanMEA_inn:InstructorTemperature | E16: {=_xll.ReadKSpice(_xlfn.CONCAT("/",$B$1,"/",$B$2,"/",D16,"@V_Unit=",F16))} -> #N/A | F16: degC | G16: =100*(E16-B16)/B16 -> #N/A | H16: Temperature Lean Solvent LeanMEA_inn
A17: TA08 | B17: =IFERROR(_xlfn.XLOOKUP(A17,'Appendix A'!A:A,'Appendix A'!E:E),"") -> 57.95 | C17: 02TIC002 | D17: 02TIC002:InternalSetpoint | E17: {=_xll.ReadKSpice(_xlfn.CONCAT("/",$B$1,"/",$B$2,"/",D17,"@V_Unit=",F17))} -> #N/A | F17: degC | G17: =100*(E17-B17)/B17 -> #N/A | H17: Temperature Lean Solvent LeanMEA_ut
A18: HE_04/05/06 | B18: =IFERROR(_xlfn.XLOOKUP(A18,'Appendix A'!A:A,'Appendix A'!E:E),"") -> 10.02 | C18: 02QIC001 | D18: 02QIC001:InternalSetpoint | E18: {=_xll.ReadKSpice(_xlfn.CONCAT("/",$B$1,"/",$B$2,"/",D18,"@V_Unit=",F18))} -> #N/A | F18: kW | G18: =100*(E18-B18)/B18 -> #N/A | H18: Reboiler Duty
A19: TAB | B19: =IFERROR(_xlfn.XLOOKUP(A19,'Appendix A'!A:A,'Appendix A'!E:E),"") -> 46.68 | C19: 00TIC000 | D19: 00TIC000:InternalSetpoint | E19: {=_xll.ReadKSpice(_xlfn.CONCAT("/",$B$1,"/",$B$2,"/",D19,"@V_Unit=",F19))} -> #N/A | F19: degC | G19: =100*(E19-B19)/B19 -> #N/A | H19: Absorber Inlet CO2 Temperature
B20: 0.22 | C20: LAL_IN | D20: LAL_IN:Output | E20: {=_xll.ReadKSpice(_xlfn.CONCAT("/",$B$1,"/",$B$2,"/",D20,"@V_Unit=",F20))} -> #N/A | F20: mol/mol | G20: =100*(E20-B20)/B20 -> #N/A | H20: CO2 Loading Lean input
A21: PI_100 | B21: =IFERROR(_xlfn.XLOOKUP(A21,'Appendix A'!A:A,'Appendix A'!E:E),"") -> 1040.05 | C21: 00PIC002 | D21: 00PIC002:InternalSetpoint | E21: {=_xll.ReadKSpice(_xlfn.CONCAT("/",$B$1,"/",$B$2,"/",D21,"@V_Unit=",F21))} -> #N/A | F21: mbara | G21: =100*(E21-B21)/B21 -> #N/A | H21: Pressure in absorber
A22: PT_02 | B22: =IFERROR(_xlfn.XLOOKUP(A22,'Appendix A'!A:A,'Appendix A'!E:E),"") -> 0.9 | C22: 04PIC001 | D22: 04PIC001:InternalSetpoint | E22: {=_xll.ReadKSpice(_xlfn.CONCAT("/",$B$1,"/",$B$2,"/",D22,"@V_Unit=",F22))} -> #N/A | F22: barg | G22: =100*(E22-B22)/B22 -> #N/A | H22: Pressure in reboiler
A23: TT_01 | B23: =IFERROR(_xlfn.XLOOKUP(A23,'Appendix A'!A:A,'Appendix A'!E:E),"") -> 30.74 | C23: 03TIC001 | D23: 03TIC001:InternalSetpoint | E23: {=_xll.ReadKSpice(_xlfn.CONCAT("/",$B$1,"/",$B$2,"/",D23,"@V_Unit=",F23))} -> #N/A | F23: degC | G23: =100*(E23-B23)/B23 -> #N/A | H23: EX03 cooling loop
A24: TT_02 | B24: =IFERROR(_xlfn.XLOOKUP(A24,'Appendix A'!A:A,'Appendix A'!E:E),"") -> 29.4 | C24: 04TIC001 | D24: 04TIC001:InternalSetpoint | E24: {=_xll.ReadKSpice(_xlfn.CONCAT("/",$B$1,"/",$B$2,"/",D24,"@V_Unit=",F24))} -> #N/A | F24: degC | G24: =100*(E24-B24)/B24 -> #N/A | H24: EX04 cooling loop
A26: FLOW INTO ABSORBER
A27: FT06 | B27: =IFERROR(_xlfn.XLOOKUP(A27,'Appendix A'!A:A,'Appendix A'!E:E),"") -> 127.02 | C27: 00FT001 | D27: 00FT001:MeasuredValue | E27: {=_xll.ReadKSpice(_xlfn.CONCAT("/",$B$1,"/",$B$2,"/",D27,"@V_Unit=",F27))} -> #N/A | F27: m3/h | G27: =100*(E27-B27)/B27 -> #N/A
A28: PI_103 | B28: =IFERROR(_xlfn.XLOOKUP(A28,'Appendix A'!A:A,'Appendix A'!E:E),"") -> 1056.4 | C28: 00PT001 | D28: 00PT001:MeasuredValue | E28: {=_xll.ReadKSpice(_xlfn.CONCAT("/",$B$1,"/",$B$2,"/",D28,"@V_Unit=",F28))} -> #N/A | F28: mbara | G28: =100*(E28-B28)/B28 -> #N/A
A29: TV5 | B29: =IFERROR(_xlfn.XLOOKUP(A29,'Appendix A'!A:A,'Appendix A'!E:E),"") -> 49.37 | C29: 00TAB000 | D29: 00TAB000:MeasuredValue | E29: {=_xll.ReadKSpice(_xlfn.CONCAT("/",$B$1,"/",$B$2,"/",D29,"@V_Unit=",F29))} -> #N/A | F29: degC | G29: =100*(E29-B29)/B29 -> #N/A
A30: FT_100 | B30: =IFERROR(_xlfn.XLOOKUP(A30,'Appendix A'!A:A,'Appendix A'!E:E),"") -> 152.07 | C30: 00FT003 | D30: 00FT003:MeasuredValue | E30: {=_xll.ReadKSpice(_xlfn.CONCAT("/",$B$1,"/",$B$2,"/",D30,"@V_Unit=",F30))} -> #N/A | F30: kg/h | G30: =100*(E30-B30)/B30 -> #N/A
A31: TA08 | B31: =IFERROR(_xlfn.XLOOKUP(A31,'Appendix A'!A:A,'Appendix A'!E:E),"") -> 57.95 | C31: LeanAmineInput | D31: LeanAmineInput:OutletStream.t | E31: {=_xll.ReadKSpice(_xlfn.CONCAT("/",$B$1,"/",$B$2,"/",D31,"@V_Unit=",F31))} -> #N/A | F31: degC | G31: =100*(E31-B31)/B31 -> #N/A | H31: Temperature Lean Solvent LeanMEA_inn
A32: TA08 | B32: =IFERROR(_xlfn.XLOOKUP(A32,'Appendix A'!A:A,'Appendix A'!E:E),"") -> 57.95 | C32: 02TT002 | D32: 02TT002:MeasuredValue | E32: {=_xll.ReadKSpice(_xlfn.CONCAT("/",$B$1,"/",$B$2,"/",D32,"@V_Unit=",F32))} -> #N/A | F32: degC | G32: =100*(E32-B32)/B32 -> #N/A | H32: Temperature Lean Solvent LeanMEA_ut
A34: ABSORBER
A35: CO2_IN | B35: =IFERROR(_xlfn.XLOOKUP(A35,'Appendix A'!A:A,'Appendix A'!E:E),"") -> 7.41 | C35: GasToAbsorber | D35: GasToAbsorber:OutputCompositionVector[4] | E35: {=_xll.ReadKSpice(_xlfn.CONCAT("/",$B$1,"/",$B$2,"/",D35,"@V_Unit=",F35))} -> #N/A | F35: % | G35: =100*(E35-B35)/B35 -> #N/A | H35: % CO2
A36: CO2_OUT (Gas) | B36: =IFERROR(_xlfn.XLOOKUP(A36,'Appendix A'!A:A,'Appendix A'!D:D),"") | C36: GasFromAbsorber | D36: GasFromAbsorber:OutputCompositionVector[4] | E36: {=_xll.ReadKSpice(_xlfn.CONCAT("/",$B$1,"/",$B$2,"/",D36,"@V_Unit=",F36))} -> #N/A | F36: % | H36: CO2 in gas form
A37: CO2_OUT (In MEA) | B37: =IFERROR(_xlfn.XLOOKUP(A37,'Appendix A'!A:A,'Appendix A'!D:D),"") | C37: GasFromAbsorber | D37: GasFromAbsorber:OutputCompositionVector[2] | E37: {=_xll.ReadKSpice(_xlfn.CONCAT("/",$B$1,"/",$B$2,"/",D37,"@V_Unit=",F37))} -> #N/A | F37: % | H37: CO2 in MEA
A38: CO2_OUT | B38: =IFERROR(_xlfn.XLOOKUP(A38,'Appendix A'!A:A,'Appendix A'!E:E),"") -> 3.05 | C38: GasFromAbsorber | E38: =E37+E36 -> #N/A | F38: % | G38: =100*(E38-B38)/B38 -> #N/A | H38: Combined CO2 % in treated gas
A39: PI_100 | B39: =IFERROR(_xlfn.XLOOKUP(A39,'Appendix A'!A:A,'Appendix A'!E:E),"") -> 1040.05 | C39: 00PI100 | D39: 00PI100:MeasuredValue | E39: {=_xll.ReadKSpice(_xlfn.CONCAT("/",$B$1,"/",$B$2,"/",D39,"@V_Unit=",F39))} -> #N/A | F39: mbara | G39: =100*(E39-B39)/B39 -> #N/A
A40: PI_102 | B40: =IFERROR(_xlfn.XLOOKUP(A40,'Appendix A'!A:A,'Appendix A'!E:E),"") -> 1048.13 | C40: 00PI102 | D40: 00PI102:MeasuredValue | E40: {=_xll.ReadKSpice(_xlfn.CONCAT("/",$B$1,"/",$B$2,"/",D40,"@V_Unit=",F40))} -> #N/A | F40: mbara | G40: =100*(E40-B40)/B40 -> #N/A
A41: TAB | B41: =IFERROR(_xlfn.XLOOKUP(A41,'Appendix A'!A:A,'Appendix A'!E:E),"") -> 46.68 | C41: 00TAB000 | D41: 00TAB000:MeasuredValue | E41: {=_xll.ReadKSpice(_xlfn.CONCAT("/",$B$1,"/",$B$2,"/",D41,"@V_Unit=",F41))} -> #N/A | F41: degC | G41: =100*(E41-B41)/B41 -> #N/A | H41: Lik TV5? Det er samme transpimmer i K-spice
A42: TA00 | B42: =IFERROR(_xlfn.XLOOKUP(A42,'Appendix A'!A:A,'Appendix A'!E:E),"") -> 47.91 | C42: 00TA000 | D42: 00TA000:MeasuredValue | E42: {=_xll.ReadKSpice(_xlfn.CONCAT("/",$B$1,"/",$B$2,"/",D42,"@V_Unit=",F42))} -> #N/A | F42: degC | G42: =100*(E42-B42)/B42 -> #N/A
A43: TA01 | B43: =IFERROR(_xlfn.XLOOKUP(A43,'Appendix A'!A:A,'Appendix A'!E:E),"") -> 48.73 | C43: 00TA001 | D43: 00TA001:MeasuredValue | E43: {=_xll.ReadKSpice(_xlfn.CONCAT("/",$B$1,"/",$B$2,"/",D43,"@V_Unit=",F43))} -> #N/A | F43: degC | G43: =100*(E43-B43)/B43 -> #N/A
A44: TA02 | B44: =IFERROR(_xlfn.XLOOKUP(A44,'Appendix A'!A:A,'Appendix A'!E:E),"") -> 48.67 | C44: 00TA002 | D44: 00TA002:MeasuredValue | E44: {=_xll.ReadKSpice(_xlfn.CONCAT("/",$B$1,"/",$B$2,"/",D44,"@V_Unit=",F44))} -> #N/A | F44: degC | G44: =100*(E44-B44)/B44 -> #N/A
A45: TA03 | B45: =IFERROR(_xlfn.XLOOKUP(A45,'Appendix A'!A:A,'Appendix A'!E:E),"") -> 48.61 | C45: 00TA003 | D45: 00TA003:MeasuredValue | E45: {=_xll.ReadKSpice(_xlfn.CONCAT("/",$B$1,"/",$B$2,"/",D45,"@V_Unit=",F45))} -> #N/A | F45: degC | G45: =100*(E45-B45)/B45 -> #N/A
...

Sheet SS case 4
A1: Timeline: | B1: Engineering
A2: Model server: | B2: ProcessModel
A4: Case: | B4: 4
A6: Fargevisning:
A7: Grønn: | B7: 0 | C7: 5
A8: Gul: | B8: 5 | C8: 10
A9: Rød: | B9: 10 | C9: 100
A11: TAG in literature | B11: Value from Appendix A | C11: TAG in model | D11: Data-tag in model | E11: SimulatedValue | F11: unit | G11: % deviation | H11: Comment
A12: SETPOINTS SET IN MCL
A13: FT06 | B13: =IFERROR(_xlfn.XLOOKUP(A13,'Appendix A'!A:A,'Appendix A'!F:F),"") -> 100.1 | C13: 00FIC001 | D13: 00FIC001:InternalSetpoint | E13: {=_xll.ReadKSpice(_xlfn.CONCAT("/",$B$1,"/",$B$2,"/",D13,"@V_Unit=",F13))} -> #N/A | F13: m3/h | G13: =100*(E13-B13)/B13 -> #N/A | H13: Gas Flow Rate
A14: FT_100 | B14: =IFERROR(_xlfn.XLOOKUP(A14,'Appendix A'!A:A,'Appendix A'!F:F),"") -> 142.13 | C14: 00FC001 | D14: 00FC001:InternalSetpoint | E14: {=_xll.ReadKSpice(_xlfn.CONCAT("/",$B$1,"/",$B$2,"/",D14,"@V_Unit=",F14))} -> #N/A | F14: kg/h | G14: =100*(E14-B14)/B14 -> #N/A | H14: Solvent Flow Rate Lean input
A15: PI_103 | B15: =IFERROR(_xlfn.XLOOKUP(A15,'Appendix A'!A:A,'Appendix A'!F:F),"") -> 1035.01 | C15: 00PIC001 | D15: 00PIC001:InternalSetpoint | E15: {=_xll.ReadKSpice(_xlfn.CONCAT("/",$B$1,"/",$B$2,"/",D15,"@V_Unit=",F15))} -> #N/A | F15: mbara | G15: =100*(E15-B15)/B15 -> #N/A | H15: Pressure of flue gas boundry
A16: TA08 | B16: =IFERROR(_xlfn.XLOOKUP(A16,'Appendix A'!A:A,'Appendix A'!F:F),"") -> 53.51 | C16: LeanMEA_inn | D16: LeanMEA_inn:InstructorTemperature | E16: {=_xll.ReadKSpice(_xlfn.CONCAT("/",$B$1,"/",$B$2,"/",D16,"@V_Unit=",F16))} -> #N/A | F16: degC | G16: =100*(E16-B16)/B16 -> #N/A | H16: Temperature Lean Solvent LeanMEA_inn
A17: TA08 | B17: =IFERROR(_xlfn.XLOOKUP(A17,'Appendix A'!A:A,'Appendix A'!F:F),"") -> 53.51 | C17: 02TIC002 | D17: 02TIC002:InternalSetpoint | E17: {=_xll.ReadKSpice(_xlfn.CONCAT("/",$B$1,"/",$B$2,"/",D17,"@V_Unit=",F17))} -> #N/A | F17: degC | G17: =100*(E17-B17)/B17 -> #N/A | H17: Temperature Lean Solvent LeanMEA_ut
A18: HE_04/05/06 | B18: =IFERROR(_xlfn.XLOOKUP(A18,'Appendix A'!A:A,'Appendix A'!F:F),"") -> 8.29 | C18: 02QIC001 | D18: 02QIC001:InternalSetpoint | E18: {=_xll.ReadKSpice(_xlfn.CONCAT("/",$B$1,"/",$B$2,"/",D18,"@V_Unit=",F18))} -> #N/A | F18: kW | G18: =100*(E18-B18)/B18 -> #N/A | H18: Reboiler Duty
A19: TAB | B19: =IFERROR(_xlfn.XLOOKUP(A19,'Appendix A'!A:A,'Appendix A'!F:F),"") -> 41.78 | C19: 00TIC000 | D19: 00TIC000:InternalSetpoint | E19: {=_xll.ReadKSpice(_xlfn.CONCAT("/",$B$1,"/",$B$2,"/",D19,"@V_Unit=",F19))} -> #N/A | F19: degC | G19: =100*(E19-B19)/B19 -> #N/A | H19: Absorber Inlet CO2 Temperature
B20: =IFERROR(_xlfn.XLOOKUP(A20,'Appendix A'!A:A,'Appendix A'!F:F),"") | C20: LAL_IN | D20: LAL_IN:Output | E20: {=_xll.ReadKSpice(_xlfn.CONCAT("/",$B$1,"/",$B$2,"/",D20,"@V_Unit=",F20))} -> #N/A | F20: mol/mol | G20: =100*(E20-B20)/B20 -> #N/A | H20: CO2 Loading Lean input
A21: PI_100 | B21: =IFERROR(_xlfn.XLOOKUP(A21,'Appendix A'!A:A,'Appendix A'!F:F),"") -> 1027.44 | C21: 00PIC002 | D21: 00PIC002:InternalSetpoint | E21: {=_xll.ReadKSpice(_xlfn.CONCAT("/",$B$1,"/",$B$2,"/",D21,"@V_Unit=",F21))} -> #N/A | F21: mbara | G21: =100*(E21-B21)/B21 -> #N/A | H21: Pressure in absorber
A22: PT_02 | B22: =IFERROR(_xlfn.XLOOKUP(A22,'Appendix A'!A:A,'Appendix A'!F:F),"") -> 0.9 | C22: 04PIC001 | D22: 04PIC001:InternalSetpoint | E22: {=_xll.ReadKSpice(_xlfn.CONCAT("/",$B$1,"/",$B$2,"/",D22,"@V_Unit=",F22))} -> #N/A | F22: barg | G22: =100*(E22-B22)/B22 -> #N/A | H22: Pressure in reboiler
A23: TT_01 | B23: =IFERROR(_xlfn.XLOOKUP(A23,'Appendix A'!A:A,'Appendix A'!F:F),"") -> 30.62 | C23: 03TIC001 | D23: 03TIC001:InternalSetpoint | E23: {=_xll.ReadKSpice(_xlfn.CONCAT("/",$B$1,"/",$B$2,"/",D23,"@V_Unit=",F23))} -> #N/A | F23: degC | G23: =100*(E23-B23)/B23 -> #N/A | H23: EX03 cooling loop
A24: TT_02 | B24: =IFERROR(_xlfn.XLOOKUP(A24,'Appendix A'!A:A,'Appendix A'!F:F),"") -> 22.57 | C24: 04TIC001 | D24: 04TIC001:InternalSetpoint | E24: {=_xll.ReadKSpice(_xlfn.CONCAT("/",$B$1,"/",$B$2,"/",D24,"@V_Unit=",F24))} -> #N/A | F24: degC | G24: =100*(E24-B24)/B24 -> #N/A | H24: EX04 cooling loop
A26: FLOW INTO ABSORBER
A27: FT06 | B27: =IFERROR(_xlfn.XLOOKUP(A27,'Appendix A'!A:A,'Appendix A'!F:F),"") -> 100.1 | C27: 00FT001 | D27: 00FT001:MeasuredValue | E27: {=_xll.ReadKSpice(_xlfn.CONCAT("/",$B$1,"/",$B$2,"/",D27,"@V_Unit=",F27))} -> #N/A | F27: m3/h | G27: =100*(E27-B27)/B27 -> #N/A
A28: PI_103 | B28: =IFERROR(_xlfn.XLOOKUP(A28,'Appendix A'!A:A,'Appendix A'!F:F),"") -> 1035.01 | C28: 00PT001 | D28: 00PT001:MeasuredValue | E28: {=_xll.ReadKSpice(_xlfn.CONCAT("/",$B$1,"/",$B$2,"/",D28,"@V_Unit=",F28))} -> #N/A | F28: mbara | G28: =100*(E28-B28)/B28 -> #N/A
A29: TV5 | B29: =IFERROR(_xlfn.XLOOKUP(A29,'Appendix A'!A:A,'Appendix A'!F:F),"") -> 43.55 | C29: 00TAB000 | D29: 00TAB000:MeasuredValue | E29: {=_xll.ReadKSpice(_xlfn.CONCAT("/",$B$1,"/",$B$2,"/",D29,"@V_Unit=",F29))} -> #N/A | F29: degC | G29: =100*(E29-B29)/B29 -> #N/A
A30: FT_100 | B30: =IFERROR(_xlfn.XLOOKUP(A30,'Appendix A'!A:A,'Appendix A'!F:F),"") -> 142.13 | C30: 00FT003 | D30: 00FT003:MeasuredValue | E30: {=_xll.ReadKSpice(_xlfn.CONCAT("/",$B$1,"/",$B$2,"/",D30,"@V_Unit=",F30))} -> #N/A | F30: kg/h | G30: =100*(E30-B30)/B30 -> #N/A
A31: TA08 | B31: =IFERROR(_xlfn.XLOOKUP(A31,'Appendix A'!A:A,'Appendix A'!F:F),"") -> 53.51 | C31: LeanAmineInput | D31: LeanAmineInput:OutletStream.t | E31: {=_xll.ReadKSpice(_xlfn.CONCAT("/",$B$1,"/",$B$2,"/",D31,"@V_Unit=",F31))} -> #N/A | F31: degC | G31: =100*(E31-B31)/B31 -> #N/A | H31: Temperature Lean Solvent LeanMEA_inn
A32: TA08 | B32: =IFERROR(_xlfn.XLOOKUP(A32,'Appendix A'!A:A,'Appendix A'!F:F),"") -> 53.51 | C32: 02TT002 | D32: 02TT002:MeasuredValue | E32: {=_xll.ReadKSpice(_xlfn.CONCAT("/",$B$1,"/",$B$2,"/",D32,"@V_Unit=",F32))} -> #N/A | F32: degC | G32: =100*(E32-B32)/B32 -> #N/A | H32: Temperature Lean Solvent LeanMEA_ut
A34: ABSORBER
A35: CO2_IN | B35: =IFERROR(_xlfn.XLOOKUP(A35,'Appendix A'!A:A,'Appendix A'!F:F),"") -> 3.57 | C35: GasToAbsorber | D35: GasToAbsorber:OutputCompositionVector[4] | E35: {=_xll.ReadKSpice(_xlfn.CONCAT("/",$B$1,"/",$B$2,"/",D35,"@V_Unit=",F35))} -> #N/A | F35: % | G35: =100*(E35-B35)/B35 -> #N/A | H35: % CO2
A36: CO2_OUT (Gas) | B36: =IFERROR(_xlfn.XLOOKUP(A36,'Appendix A'!A:A,'Appendix A'!D:D),"") | C36: GasFromAbsorber | D36: GasFromAbsorber:OutputCompositionVector[4] | E36: {=_xll.ReadKSpice(_xlfn.CONCAT("/",$B$1,"/",$B$2,"/",D36,"@V_Unit=",F36))} -> #N/A | F36: % | H36: CO2 in gas form
A37: CO2_OUT (In MEA) | B37: =IFERROR(_xlfn.XLOOKUP(A37,'Appendix A'!A:A,'Appendix A'!D:D),"") | C37: GasFromAbsorber | D37: GasFromAbsorber:OutputCompositionVector[2] | E37: {=_xll.ReadKSpice(_xlfn.CONCAT("/",$B$1,"/",$B$2,"/",D37,"@V_Unit=",F37))} -> #N/A | F37: % | H37: CO2 in MEA
A38: CO2_OUT | B38: =IFERROR(_xlfn.XLOOKUP(A38,'Appendix A'!A:A,'Appendix A'!F:F),"") -> 0 | C38: GasFromAbsorber | E38: =E37+E36 -> #N/A | F38: % | G38: =100*(E38-B38)/B38 -> #N/A | H38: Combined CO2 % in treated gas
A39: PI_100 | B39: =IFERROR(_xlfn.XLOOKUP(A39,'Appendix A'!A:A,'Appendix A'!F:F),"") -> 1027.44 | C39: 00PI100 | D39: 00PI100:MeasuredValue | E39: {=_xll.ReadKSpice(_xlfn.CONCAT("/",$B$1,"/",$B$2,"/",D39,"@V_Unit=",F39))} -> #N/A | F39: mbara | G39: =100*(E39-B39)/B39 -> #N/A
A40: PI_102 | B40: =IFERROR(_xlfn.XLOOKUP(A40,'Appendix A'!A:A,'Appendix A'!F:F),"") -> 1032.3 | C40: 00PI102 | D40: 00PI102:MeasuredValue | E40: {=_xll.ReadKSpice(_xlfn.CONCAT("/",$B$1,"/",$B$2,"/",D40,"@V_Unit=",F40))} -> #N/A | F40: mbara | G40: =100*(E40-B40)/B40 -> #N/A
A41: TAB | B41: =IFERROR(_xlfn.XLOOKUP(A41,'Appendix A'!A:A,'Appendix A'!F:F),"") -> 41.78 | C41: 00TAB000 | D41: 00TAB000:MeasuredValue | E41: {=_xll.ReadKSpice(_xlfn.CONCAT("/",$B$1,"/",$B$2,"/",D41,"@V_Unit=",F41))} -> #N/A | F41: degC | G41: =100*(E41-B41)/B41 -> #N/A | H41: Lik TV5? Det er samme transpimmer i K-spice
A42: TA00 | B42: =IFERROR(_xlfn.XLOOKUP(A42,'Appendix A'!A:A,'Appendix A'!F:F),"") -> 44.15 | C42: 00TA000 | D42: 00TA000:MeasuredValue | E42: {=_xll.ReadKSpice(_xlfn.CONCAT("/",$B$1,"/",$B$2,"/",D42,"@V_Unit=",F42))} -> #N/A | F42: degC | G42: =100*(E42-B42)/B42 -> #N/A
A43: TA01 | B43: =IFERROR(_xlfn.XLOOKUP(A43,'Appendix A'!A:A,'Appendix A'!F:F),"") -> 45.3 | C43: 00TA001 | D43: 00TA001:MeasuredValue | E43: {=_xll.ReadKSpice(_xlfn.CONCAT("/",$B$1,"/",$B$2,"/",D43,"@V_Unit=",F43))} -> #N/A | F43: degC | G43: =100*(E43-B43)/B43 -> #N/A
A44: TA02 | B44: =IFERROR(_xlfn.XLOOKUP(A44,'Appendix A'!A:A,'Appendix A'!F:F),"") -> 47.59 | C44: 00TA002 | D44: 00TA002:MeasuredValue | E44: {=_xll.ReadKSpice(_xlfn.CONCAT("/",$B$1,"/",$B$2,"/",D44,"@V_Unit=",F44))} -> #N/A | F44: degC | G44: =100*(E44-B44)/B44 -> #N/A
A45: TA03 | B45: =IFERROR(_xlfn.XLOOKUP(A45,'Appendix A'!A:A,'Appendix A'!F:F),"") -> 49.28 | C45: 00TA003 | D45: 00TA003:MeasuredValue | E45: {=_xll.ReadKSpice(_xlfn.CONCAT("/",$B$1,"/",$B$2,"/",D45,"@V_Unit=",F45))} -> #N/A | F45: degC | G45: =100*(E45-B45)/B45 -> #N/A
...

Sheet SS case 5
A1: Timeline: | B1: Engineering
A2: Model server: | B2: ProcessModel
A4: Case: | B4: 5
A6: Fargevisning:
A7: Grønn: | B7: 0 | C7: 5
A8: Gul: | B8: 5 | C8: 10
A9: Rød: | B9: 10 | C9: 100
A11: TAG in literature | B11: Value from Appendix A | C11: TAG in model | D11: Data-tag in model | E11: SimulatedValue | F11: unit | G11: % deviation | H11: Comment
A12: SETPOINTS SET IN MCL
A13: FT06 | B13: =IFERROR(_xlfn.XLOOKUP(A13,'Appendix A'!A:A,'Appendix A'!G:G),"") -> 125.94 | C13: 00FIC001 | D13: 00FIC001:InternalSetpoint | E13: {=_xll.ReadKSpice(_xlfn.CONCAT("/",$B$1,"/",$B$2,"/",D13,"@V_Unit=",F13))} -> #N/A | F13: m3/h | G13: =100*(E13-B13)/B13 -> #N/A | H13: Gas Flow Rate
A14: FT_100 | B14: =IFERROR(_xlfn.XLOOKUP(A14,'Appendix A'!A:A,'Appendix A'!G:G),"") -> 240.87 | C14: 00FC001 | D14: 00FC001:InternalSetpoint | E14: {=_xll.ReadKSpice(_xlfn.CONCAT("/",$B$1,"/",$B$2,"/",D14,"@V_Unit=",F14))} -> #N/A | F14: kg/h | G14: =100*(E14-B14)/B14 -> #N/A | H14: Solvent Flow Rate Lean input
A15: PI_103 | B15: =IFERROR(_xlfn.XLOOKUP(A15,'Appendix A'!A:A,'Appendix A'!G:G),"") -> 1029 | C15: 00PIC001 | D15: 00PIC001:InternalSetpoint | E15: {=_xll.ReadKSpice(_xlfn.CONCAT("/",$B$1,"/",$B$2,"/",D15,"@V_Unit=",F15))} -> #N/A | F15: mbara | G15: =100*(E15-B15)/B15 -> #N/A | H15: Pressure of flue gas boundry
A16: TA08 | B16: =IFERROR(_xlfn.XLOOKUP(A16,'Appendix A'!A:A,'Appendix A'!G:G),"") -> 52.17 | C16: LeanMEA_inn | D16: LeanMEA_inn:InstructorTemperature | E16: {=_xll.ReadKSpice(_xlfn.CONCAT("/",$B$1,"/",$B$2,"/",D16,"@V_Unit=",F16))} -> #N/A | F16: degC | G16: =100*(E16-B16)/B16 -> #N/A | H16: Temperature Lean Solvent LeanMEA_inn
A17: TA08 | B17: =IFERROR(_xlfn.XLOOKUP(A17,'Appendix A'!A:A,'Appendix A'!G:G),"") -> 52.17 | C17: 02TIC002 | D17: 02TIC002:InternalSetpoint | E17: {=_xll.ReadKSpice(_xlfn.CONCAT("/",$B$1,"/",$B$2,"/",D17,"@V_Unit=",F17))} -> #N/A | F17: degC | G17: =100*(E17-B17)/B17 -> #N/A | H17: Temperature Lean Solvent LeanMEA_ut
A18: HE_04/05/06 | B18: =IFERROR(_xlfn.XLOOKUP(A18,'Appendix A'!A:A,'Appendix A'!G:G),"") -> 10.35 | C18: 02QIC001 | D18: 02QIC001:InternalSetpoint | E18: {=_xll.ReadKSpice(_xlfn.CONCAT("/",$B$1,"/",$B$2,"/",D18,"@V_Unit=",F18))} -> #N/A | F18: kW | G18: =100*(E18-B18)/B18 -> #N/A | H18: Reboiler Duty
A19: TAB | B19: =IFERROR(_xlfn.XLOOKUP(A19,'Appendix A'!A:A,'Appendix A'!G:G),"") -> 44.38 | C19: 00TIC000 | D19: 00TIC000:InternalSetpoint | E19: {=_xll.ReadKSpice(_xlfn.CONCAT("/",$B$1,"/",$B$2,"/",D19,"@V_Unit=",F19))} -> #N/A | F19: degC | G19: =100*(E19-B19)/B19 -> #N/A | H19: Absorber Inlet CO2 Temperature
B20: 0.27 | C20: LAL_IN | D20: LAL_IN:Output | E20: {=_xll.ReadKSpice(_xlfn.CONCAT("/",$B$1,"/",$B$2,"/",D20,"@V_Unit=",F20))} -> #N/A | F20: mol/mol | G20: =100*(E20-B20)/B20 -> #N/A | H20: CO2 Loading Lean input
A21: PI_100 | B21: =IFERROR(_xlfn.XLOOKUP(A21,'Appendix A'!A:A,'Appendix A'!G:G),"") -> 1012.1 | C21: 00PIC002 | D21: 00PIC002:InternalSetpoint | E21: {=_xll.ReadKSpice(_xlfn.CONCAT("/",$B$1,"/",$B$2,"/",D21,"@V_Unit=",F21))} -> #N/A | F21: mbara | G21: =100*(E21-B21)/B21 -> #N/A | H21: Pressure in absorber
A22: PT_02 | B22: =IFERROR(_xlfn.XLOOKUP(A22,'Appendix A'!A:A,'Appendix A'!G:G),"") -> 0.9 | C22: 04PIC001 | D22: 04PIC001:InternalSetpoint | E22: {=_xll.ReadKSpice(_xlfn.CONCAT("/",$B$1,"/",$B$2,"/",D22,"@V_Unit=",F22))} -> #N/A | F22: barg | G22: =100*(E22-B22)/B22 -> #N/A | H22: Pressure in reboiler
A23: TT_01 | B23: =IFERROR(_xlfn.XLOOKUP(A23,'Appendix A'!A:A,'Appendix A'!G:G),"") -> 30.62 | C23: 03TIC001 | D23: 03TIC001:InternalSetpoint | E23: {=_xll.ReadKSpice(_xlfn.CONCAT("/",$B$1,"/",$B$2,"/",D23,"@V_Unit=",F23))} -> #N/A | F23: degC | G23: =100*(E23-B23)/B23 -> #N/A | H23: EX03 cooling loop
A24: TT_02 | B24: =IFERROR(_xlfn.XLOOKUP(A24,'Appendix A'!A:A,'Appendix A'!G:G),"") -> 25.99 | C24: 04TIC001 | D24: 04TIC001:InternalSetpoint | E24: {=_xll.ReadKSpice(_xlfn.CONCAT("/",$B$1,"/",$B$2,"/",D24,"@V_Unit=",F24))} -> #N/A | F24: degC | G24: =100*(E24-B24)/B24 -> #N/A | H24: EX04 cooling loop
A26: FLOW INTO ABSORBER
A27: FT06 | B27: =IFERROR(_xlfn.XLOOKUP(A27,'Appendix A'!A:A,'Appendix A'!G:G),"") -> 125.94 | C27: 00FT001 | D27: 00FT001:MeasuredValue | E27: {=_xll.ReadKSpice(_xlfn.CONCAT("/",$B$1,"/",$B$2,"/",D27,"@V_Unit=",F27))} -> #N/A | F27: m3/h | G27: =100*(E27-B27)/B27 -> #N/A
A28: PI_103 | B28: =IFERROR(_xlfn.XLOOKUP(A28,'Appendix A'!A:A,'Appendix A'!G:G),"") -> 1029 | C28: 00PT001 | D28: 00PT001:MeasuredValue | E28: {=_xll.ReadKSpice(_xlfn.CONCAT("/",$B$1,"/",$B$2,"/",D28,"@V_Unit=",F28))} -> #N/A | F28: mbara | G28: =100*(E28-B28)/B28 -> #N/A
A29: TV5 | B29: =IFERROR(_xlfn.XLOOKUP(A29,'Appendix A'!A:A,'Appendix A'!G:G),"") -> 47.16 | C29: 00TAB000 | D29: 00TAB000:MeasuredValue | E29: {=_xll.ReadKSpice(_xlfn.CONCAT("/",$B$1,"/",$B$2,"/",D29,"@V_Unit=",F29))} -> #N/A | F29: degC | G29: =100*(E29-B29)/B29 -> #N/A
A30: FT_100 | B30: =IFERROR(_xlfn.XLOOKUP(A30,'Appendix A'!A:A,'Appendix A'!G:G),"") -> 240.87 | C30: 00FT003 | D30: 00FT003:MeasuredValue | E30: {=_xll.ReadKSpice(_xlfn.CONCAT("/",$B$1,"/",$B$2,"/",D30,"@V_Unit=",F30))} -> #N/A | F30: kg/h | G30: =100*(E30-B30)/B30 -> #N/A
A31: TA08 | B31: =IFERROR(_xlfn.XLOOKUP(A31,'Appendix A'!A:A,'Appendix A'!G:G),"") -> 52.17 | C31: LeanAmineInput | D31: LeanAmineInput:OutletStream.t | E31: {=_xll.ReadKSpice(_xlfn.CONCAT("/",$B$1,"/",$B$2,"/",D31,"@V_Unit=",F31))} -> #N/A | F31: degC | G31: =100*(E31-B31)/B31 -> #N/A | H31: Temperature Lean Solvent LeanMEA_inn
A32: TA08 | B32: =IFERROR(_xlfn.XLOOKUP(A32,'Appendix A'!A:A,'Appendix A'!G:G),"") -> 52.17 | C32: 02TT002 | D32: 02TT002:MeasuredValue | E32: {=_xll.ReadKSpice(_xlfn.CONCAT("/",$B$1,"/",$B$2,"/",D32,"@V_Unit=",F32))} -> #N/A | F32: degC | G32: =100*(E32-B32)/B32 -> #N/A | H32: Temperature Lean Solvent LeanMEA_ut
A34: ABSORBER
A35: CO2_IN | B35: =IFERROR(_xlfn.XLOOKUP(A35,'Appendix A'!A:A,'Appendix A'!G:G),"") -> 3.9 | C35: GasToAbsorber | D35: GasToAbsorber:OutputCompositionVector[4] | E35: {=_xll.ReadKSpice(_xlfn.CONCAT("/",$B$1,"/",$B$2,"/",D35,"@V_Unit=",F35))} -> #N/A | F35: % | G35: =100*(E35-B35)/B35 -> #N/A | H35: % CO2
A36: CO2_OUT (Gas) | B36: =IFERROR(_xlfn.XLOOKUP(A36,'Appendix A'!A:A,'Appendix A'!D:D),"") | C36: GasFromAbsorber | D36: GasFromAbsorber:OutputCompositionVector[4] | E36: {=_xll.ReadKSpice(_xlfn.CONCAT("/",$B$1,"/",$B$2,"/",D36,"@V_Unit=",F36))} -> #N/A | F36: % | H36: CO2 in gas form
A37: CO2_OUT (In MEA) | B37: =IFERROR(_xlfn.XLOOKUP(A37,'Appendix A'!A:A,'Appendix A'!D:D),"") | C37: GasFromAbsorber | D37: GasFromAbsorber:OutputCompositionVector[2] | E37: {=_xll.ReadKSpice(_xlfn.CONCAT("/",$B$1,"/",$B$2,"/",D37,"@V_Unit=",F37))} -> #N/A | F37: % | H37: CO2 in MEA
A38: CO2_OUT | B38: =IFERROR(_xlfn.XLOOKUP(A38,'Appendix A'!A:A,'Appendix A'!G:G),"") -> 0.44 | C38: GasFromAbsorber | E38: =E37+E36 -> #N/A | F38: % | G38: =100*(E38-B38)/B38 -> #N/A | H38: Combined CO2 % in treated gas
A39: PI_100 | B39: =IFERROR(_xlfn.XLOOKUP(A39,'Appendix A'!A:A,'Appendix A'!G:G),"") -> 1012.1 | C39: 00PI100 | D39: 00PI100:MeasuredValue | E39: {=_xll.ReadKSpice(_xlfn.CONCAT("/",$B$1,"/",$B$2,"/",D39,"@V_Unit=",F39))} -> #N/A | F39: mbara | G39: =100*(E39-B39)/B39 -> #N/A
A40: PI_102 | B40: =IFERROR(_xlfn.XLOOKUP(A40,'Appendix A'!A:A,'Appendix A'!G:G),"") -> 1020.73 | C40: 00PI102 | D40: 00PI102:MeasuredValue | E40: {=_xll.ReadKSpice(_xlfn.CONCAT("/",$B$1,"/",$B$2,"/",D40,"@V_Unit=",F40))} -> #N/A | F40: mbara | G40: =100*(E40-B40)/B40 -> #N/A
A41: TAB | B41: =IFERROR(_xlfn.XLOOKUP(A41,'Appendix A'!A:A,'Appendix A'!G:G),"") -> 44.38 | C41: 00TAB000 | D41: 00TAB000:MeasuredValue | E41: {=_xll.ReadKSpice(_xlfn.CONCAT("/",$B$1,"/",$B$2,"/",D41,"@V_Unit=",F41))} -> #N/A | F41: degC | G41: =100*(E41-B41)/B41 -> #N/A | H41: Lik TV5? Det er samme transpimmer i K-spice
A42: TA00 | B42: =IFERROR(_xlfn.XLOOKUP(A42,'Appendix A'!A:A,'Appendix A'!G:G),"") -> 45.55 | C42: 00TA000 | D42: 00TA000:MeasuredValue | E42: {=_xll.ReadKSpice(_xlfn.CONCAT("/",$B$1,"/",$B$2,"/",D42,"@V_Unit=",F42))} -> #N/A | F42: degC | G42: =100*(E42-B42)/B42 -> #N/A
A43: TA01 | B43: =IFERROR(_xlfn.XLOOKUP(A43,'Appendix A'!A:A,'Appendix A'!G:G),"") -> 47.05 | C43: 00TA001 | D43: 00TA001:MeasuredValue | E43: {=_xll.ReadKSpice(_xlfn.CONCAT("/",$B$1,"/",$B$2,"/",D43,"@V_Unit=",F43))} -> #N/A | F43: degC | G43: =100*(E43-B43)/B43 -> #N/A
A44: TA02 | B44: =IFERROR(_xlfn.XLOOKUP(A44,'Appendix A'!A:A,'Appendix A'!G:G),"") -> 50.02 | C44: 00TA002 | D44: 00TA002:MeasuredValue | E44: {=_xll.ReadKSpice(_xlfn.CONCAT("/",$B$1,"/",$B$2,"/",D44,"@V_Unit=",F44))} -> #N/A | F44: degC | G44: =100*(E44-B44)/B44 -> #N/A
A45: TA03 | B45: =IFERROR(_xlfn.XLOOKUP(A45,'Appendix A'!A:A,'Appendix A'!G:G),"") -> 51.8 | C45: 00TA003 | D45: 00TA003:MeasuredValue | E45: {=_xll.ReadKSpice(_xlfn.CONCAT("/",$B$1,"/",$B$2,"/",D45,"@V_Unit=",F45))} -> #N/A | F45: degC | G45: =100*(E45-B45)/B45 -> #N/A
...

Sheet SS case 6
A1: Timeline: | B1: Engineering
A2: Model server: | B2: ProcessModel
A4: Case: | B4: 6
A6: Fargevisning:
A7: Grønn: | B7: 0 | C7: 5
A8: Gul: | B8: 5 | C8: 10
A9: Rød: | B9: 10 | C9: 100
A11: TAG in literature | B11: Value from Appendix A | C11: TAG in model | D11: Data-tag in model | E11: SimulatedValue | F11: unit | G11: % deviation | H11: Comment
A12: SETPOINTS SET IN MCL
A13: FT06 | B13: =IFERROR(_xlfn.XLOOKUP(A13,'Appendix A'!A:A,'Appendix A'!H:H),"") -> 118.96 | C13: 00FIC001 | D13: 00FIC001:InternalSetpoint | E13: {=_xll.ReadKSpice(_xlfn.CONCAT("/",$B$1,"/",$B$2,"/",D13,"@V_Unit=",F13))} -> #N/A | F13: m3/h | G13: =100*(E13-B13)/B13 -> #N/A | H13: Gas Flow Rate
A14: FT_100 | B14: =IFERROR(_xlfn.XLOOKUP(A14,'Appendix A'!A:A,'Appendix A'!H:H),"") -> 178.72 | C14: 00FC001 | D14: 00FC001:InternalSetpoint | E14: {=_xll.ReadKSpice(_xlfn.CONCAT("/",$B$1,"/",$B$2,"/",D14,"@V_Unit=",F14))} -> #N/A | F14: kg/h | G14: =100*(E14-B14)/B14 -> #N/A | H14: Solvent Flow Rate Lean input
A15: PI_103 | B15: =IFERROR(_xlfn.XLOOKUP(A15,'Appendix A'!A:A,'Appendix A'!H:H),"") -> 1042.66 | C15: 00PIC001 | D15: 00PIC001:InternalSetpoint | E15: {=_xll.ReadKSpice(_xlfn.CONCAT("/",$B$1,"/",$B$2,"/",D15,"@V_Unit=",F15))} -> #N/A | F15: mbara | G15: =100*(E15-B15)/B15 -> #N/A | H15: Pressure of flue gas boundry
A16: TA08 | B16: =IFERROR(_xlfn.XLOOKUP(A16,'Appendix A'!A:A,'Appendix A'!H:H),"") -> 46.94 | C16: LeanMEA_inn | D16: LeanMEA_inn:InstructorTemperature | E16: {=_xll.ReadKSpice(_xlfn.CONCAT("/",$B$1,"/",$B$2,"/",D16,"@V_Unit=",F16))} -> #N/A | F16: degC | G16: =100*(E16-B16)/B16 -> #N/A | H16: Temperature Lean Solvent LeanMEA_inn
A17: TA08 | B17: =IFERROR(_xlfn.XLOOKUP(A17,'Appendix A'!A:A,'Appendix A'!H:H),"") -> 46.94 | C17: 02TIC002 | D17: 02TIC002:InternalSetpoint | E17: {=_xll.ReadKSpice(_xlfn.CONCAT("/",$B$1,"/",$B$2,"/",D17,"@V_Unit=",F17))} -> #N/A | F17: degC | G17: =100*(E17-B17)/B17 -> #N/A | H17: Temperature Lean Solvent LeanMEA_ut
A18: HE_04/05/06 | B18: =IFERROR(_xlfn.XLOOKUP(A18,'Appendix A'!A:A,'Appendix A'!H:H),"") -> 6.13 | C18: 02QIC001 | D18: 02QIC001:InternalSetpoint | E18: {=_xll.ReadKSpice(_xlfn.CONCAT("/",$B$1,"/",$B$2,"/",D18,"@V_Unit=",F18))} -> #N/A | F18: kW | G18: =100*(E18-B18)/B18 -> #N/A | H18: Reboiler Duty
A19: TAB | B19: =IFERROR(_xlfn.XLOOKUP(A19,'Appendix A'!A:A,'Appendix A'!H:H),"") -> 38.93 | C19: 00TIC000 | D19: 00TIC000:InternalSetpoint | E19: {=_xll.ReadKSpice(_xlfn.CONCAT("/",$B$1,"/",$B$2,"/",D19,"@V_Unit=",F19))} -> #N/A | F19: degC | G19: =100*(E19-B19)/B19 -> #N/A | H19: Absorber Inlet CO2 Temperature
B20: 0.34 | C20: LAL_IN | D20: LAL_IN:Output | E20: {=_xll.ReadKSpice(_xlfn.CONCAT("/",$B$1,"/",$B$2,"/",D20,"@V_Unit=",F20))} -> #N/A | F20: mol/mol | G20: =100*(E20-B20)/B20 -> #N/A | H20: CO2 Loading Lean input
A21: PI_100 | B21: =IFERROR(_xlfn.XLOOKUP(A21,'Appendix A'!A:A,'Appendix A'!H:H),"") -> 1030.53 | C21: 00PIC002 | D21: 00PIC002:InternalSetpoint | E21: {=_xll.ReadKSpice(_xlfn.CONCAT("/",$B$1,"/",$B$2,"/",D21,"@V_Unit=",F21))} -> #N/A | F21: mbara | G21: =100*(E21-B21)/B21 -> #N/A | H21: Pressure in absorber
A22: PT_02 | B22: =IFERROR(_xlfn.XLOOKUP(A22,'Appendix A'!A:A,'Appendix A'!H:H),"") -> 0.7 | C22: 04PIC001 | D22: 04PIC001:InternalSetpoint | E22: {=_xll.ReadKSpice(_xlfn.CONCAT("/",$B$1,"/",$B$2,"/",D22,"@V_Unit=",F22))} -> #N/A | F22: barg | G22: =100*(E22-B22)/B22 -> #N/A | H22: Pressure in reboiler
A23: TT_01 | B23: =IFERROR(_xlfn.XLOOKUP(A23,'Appendix A'!A:A,'Appendix A'!H:H),"") -> 30.63 | C23: 03TIC001 | D23: 03TIC001:InternalSetpoint | E23: {=_xll.ReadKSpice(_xlfn.CONCAT("/",$B$1,"/",$B$2,"/",D23,"@V_Unit=",F23))} -> #N/A | F23: degC | G23: =100*(E23-B23)/B23 -> #N/A | H23: EX03 cooling loop
A24: TT_02 | B24: =IFERROR(_xlfn.XLOOKUP(A24,'Appendix A'!A:A,'Appendix A'!H:H),"") -> 16.98 | C24: 04TIC001 | D24: 04TIC001:InternalSetpoint | E24: {=_xll.ReadKSpice(_xlfn.CONCAT("/",$B$1,"/",$B$2,"/",D24,"@V_Unit=",F24))} -> #N/A | F24: degC | G24: =100*(E24-B24)/B24 -> #N/A | H24: EX04 cooling loop
A26: FLOW INTO ABSORBER
A27: FT06 | B27: =IFERROR(_xlfn.XLOOKUP(A27,'Appendix A'!A:A,'Appendix A'!H:H),"") -> 118.96 | C27: 00FT001 | D27: 00FT001:MeasuredValue | E27: {=_xll.ReadKSpice(_xlfn.CONCAT("/",$B$1,"/",$B$2,"/",D27,"@V_Unit=",F27))} -> #N/A | F27: m3/h | G27: =100*(E27-B27)/B27 -> #N/A
A28: PI_103 | B28: =IFERROR(_xlfn.XLOOKUP(A28,'Appendix A'!A:A,'Appendix A'!H:H),"") -> 1042.66 | C28: 00PT001 | D28: 00PT001:MeasuredValue | E28: {=_xll.ReadKSpice(_xlfn.CONCAT("/",$B$1,"/",$B$2,"/",D28,"@V_Unit=",F28))} -> #N/A | F28: mbara | G28: =100*(E28-B28)/B28 -> #N/A
A29: TV5 | B29: =IFERROR(_xlfn.XLOOKUP(A29,'Appendix A'!A:A,'Appendix A'!H:H),"") -> 40.71 | C29: 00TAB000 | D29: 00TAB000:MeasuredValue | E29: {=_xll.ReadKSpice(_xlfn.CONCAT("/",$B$1,"/",$B$2,"/",D29,"@V_Unit=",F29))} -> #N/A | F29: degC | G29: =100*(E29-B29)/B29 -> #N/A
A30: FT_100 | B30: =IFERROR(_xlfn.XLOOKUP(A30,'Appendix A'!A:A,'Appendix A'!H:H),"") -> 178.72 | C30: 00FT003 | D30: 00FT003:MeasuredValue | E30: {=_xll.ReadKSpice(_xlfn.CONCAT("/",$B$1,"/",$B$2,"/",D30,"@V_Unit=",F30))} -> #N/A | F30: kg/h | G30: =100*(E30-B30)/B30 -> #N/A
A31: TA08 | B31: =IFERROR(_xlfn.XLOOKUP(A31,'Appendix A'!A:A,'Appendix A'!H:H),"") -> 46.94 | C31: LeanAmineInput | D31: LeanAmineInput:OutletStream.t | E31: {=_xll.ReadKSpice(_xlfn.CONCAT("/",$B$1,"/",$B$2,"/",D31,"@V_Unit=",F31))} -> #N/A | F31: degC | G31: =100*(E31-B31)/B31 -> #N/A | H31: Temperature Lean Solvent LeanMEA_inn
A32: TA08 | B32: =IFERROR(_xlfn.XLOOKUP(A32,'Appendix A'!A:A,'Appendix A'!H:H),"") -> 46.94 | C32: 02TT002 | D32: 02TT002:MeasuredValue | E32: {=_xll.ReadKSpice(_xlfn.CONCAT("/",$B$1,"/",$B$2,"/",D32,"@V_Unit=",F32))} -> #N/A | F32: degC | G32: =100*(E32-B32)/B32 -> #N/A | H32: Temperature Lean Solvent LeanMEA_ut
A34: ABSORBER
A35: CO2_IN | B35: =IFERROR(_xlfn.XLOOKUP(A35,'Appendix A'!A:A,'Appendix A'!H:H),"") -> 5.41 | C35: GasToAbsorber | D35: GasToAbsorber:OutputCompositionVector[4] | E35: {=_xll.ReadKSpice(_xlfn.CONCAT("/",$B$1,"/",$B$2,"/",D35,"@V_Unit=",F35))} -> #N/A | F35: % | G35: =100*(E35-B35)/B35 -> #N/A | H35: % CO2
A36: CO2_OUT (Gas) | B36: =IFERROR(_xlfn.XLOOKUP(A36,'Appendix A'!A:A,'Appendix A'!D:D),"") | C36: GasFromAbsorber | D36: GasFromAbsorber:OutputCompositionVector[4] | E36: {=_xll.ReadKSpice(_xlfn.CONCAT("/",$B$1,"/",$B$2,"/",D36,"@V_Unit=",F36))} -> #N/A | F36: % | H36: CO2 in gas form
A37: CO2_OUT (In MEA) | B37: =IFERROR(_xlfn.XLOOKUP(A37,'Appendix A'!A:A,'Appendix A'!D:D),"") | C37: GasFromAbsorber | D37: GasFromAbsorber:OutputCompositionVector[2] | E37: {=_xll.ReadKSpice(_xlfn.CONCAT("/",$B$1,"/",$B$2,"/",D37,"@V_Unit=",F37))} -> #N/A | F37: % | H37: CO2 in MEA
A38: CO2_OUT | B38: =IFERROR(_xlfn.XLOOKUP(A38,'Appendix A'!A:A,'Appendix A'!H:H),"") -> 3.09 | C38: GasFromAbsorber | E38: =E37+E36 -> #N/A | F38: % | G38: =100*(E38-B38)/B38 -> #N/A | H38: Combined CO2 % in treated gas
A39: PI_100 | B39: =IFERROR(_xlfn.XLOOKUP(A39,'Appendix A'!A:A,'Appendix A'!H:H),"") -> 1030.53 | C39: 00PI100 | D39: 00PI100:MeasuredValue | E39: {=_xll.ReadKSpice(_xlfn.CONCAT("/",$B$1,"/",$B$2,"/",D39,"@V_Unit=",F39))} -> #N/A | F39: mbara | G39: =100*(E39-B39)/B39 -> #N/A
A40: PI_102 | B40: =IFERROR(_xlfn.XLOOKUP(A40,'Appendix A'!A:A,'Appendix A'!H:H),"") -> 1038.75 | C40: 00PI102 | D40: 00PI102:MeasuredValue | E40: {=_xll.ReadKSpice(_xlfn.CONCAT("/",$B$1,"/",$B$2,"/",D40,"@V_Unit=",F40))} -> #N/A | F40: mbara | G40: =100*(E40-B40)/B40 -> #N/A
A41: TAB | B41: =IFERROR(_xlfn.XLOOKUP(A41,'Appendix A'!A:A,'Appendix A'!H:H),"") -> 38.93 | C41: 00TAB000 | D41: 00TAB000:MeasuredValue | E41: {=_xll.ReadKSpice(_xlfn.CONCAT("/",$B$1,"/",$B$2,"/",D41,"@V_Unit=",F41))} -> #N/A | F41: degC | G41: =100*(E41-B41)/B41 -> #N/A | H41: Lik TV5? Det er samme transpimmer i K-spice
A42: TA00 | B42: =IFERROR(_xlfn.XLOOKUP(A42,'Appendix A'!A:A,'Appendix A'!H:H),"") -> 35.78 | C42: 00TA000 | D42: 00TA000:MeasuredValue | E42: {=_xll.ReadKSpice(_xlfn.CONCAT("/",$B$1,"/",$B$2,"/",D42,"@V_Unit=",F42))} -> #N/A | F42: degC | G42: =100*(E42-B42)/B42 -> #N/A
A43: TA01 | B43: =IFERROR(_xlfn.XLOOKUP(A43,'Appendix A'!A:A,'Appendix A'!H:H),"") -> 36.56 | C43: 00TA001 | D43: 00TA001:MeasuredValue | E43: {=_xll.ReadKSpice(_xlfn.CONCAT("/",$B$1,"/",$B$2,"/",D43,"@V_Unit=",F43))} -> #N/A | F43: degC | G43: =100*(E43-B43)/B43 -> #N/A
