Workbook

Sheet Appendix A
B1: Enhet | C1: Case1 | D1: Case2 | E1: Case3 | F1: Case4 | G1: Case5 | H1: Case6 | I1: Case7 | J1: Case8 | N1: Absorber-høyder | P1: Stripper høyder | R1: Case | S1: Tot Avvik | T1: KPI avvik
A2: CO2_IN | B2: dry % | C2: 3.52 | D2: 6.77 | E2: 7.41 | F2: 3.57 | G2: 3.9 | H2: 5.41 | I2: 4.57 | J2: 1.55 | N2: 1 | P2: 0 | R2: 1 | S2: 5.3414388 | T2: 9.8841281
A3: CO2_OUT | B3: dry % | C3: 0.29 | D3: 1.19 | E3: 3.05 | F3: 0 | G3: 0.44 | H3: 3.09 | I3: 1.38 | J3: 0 | N3: 2 | P3: 1 | R3: 2 | S3: 9.0133989 | T3: 8.2608676
A4: FT_100 | B4: kg/h | C4: 166.93 | D4: 172.33 | E4: 152.07 | F4: 142.13 | G4: 240.87 | H4: 178.72 | I4: 238.82 | J4: 239.09 | N4: 3 | P4: 2 | R4: 3 | S4: 9.1575025 | T4: 5.0984884
A5: FT_101 | B5: kg/h | C5: 171.04 | D5: 179.79 | E5: 156.95 | F5: 146.43 | G5: 246.13 | H5: 180.31 | I5: 241.74 | J5: 240.34 | N5: 4 | P5: 3 | R5: 5 | S5: 5.6683996 | T5: 7.2986775
A6: FT06 | B6: m³/h | C6: 89.77 | D6: 90.09 | E6: 127.02 | F6: 100.1 | G6: 125.94 | H6: 118.96 | I6: 118.87 | J6: 118.57 | N6: 5 | P6: 4 | R6: 6 | S6: 8.1796378 | T6: 15.201889
A7: FT_EH | B7: kg/h | C7: 2.91 | D7: 4.16 | E7: 4.6 | F7: 3.93 | G7: 5.56 | H7: 2.11 | I7: 3.49 | J7: 5.42 | N7: 6 | R7: 7 | S7: 8.5353452 | T7: 18.876674
A8: FT_EM | B8: kg/h | C8: 4.41 | D8: 7.71 | E8: 8.99 | F8: 6.53 | G8: 7.21 | H8: 4.95 | I8: 6.63 | J8: 3.25 | N8: 7
A9: FT_VASK | B9: kg/h | C9: 23.51 | D9: 23.21 | E9: 294.18 | F9: 271 | G9: 264.18 | H9: 196.66 | I9: 228.23 | J9: 251.49
A10: HE_04/05/06 | B10: kW | C10: 6.82 | D10: 9.23 | E10: 10.02 | F10: 8.29 | G10: 10.35 | H10: 6.13 | I10: 8.33 | J10: 8.26
A11: LT_01 | B11: L | C11: 11.32 | D11: 11.32 | E11: 11.32 | F11: 11.32 | G11: 11.67 | H11: 11.95 | I11: 11.95 | J11: 11.95
A12: LT_02 | B12: L | C12: 54.03 | D12: 53.31 | E12: 53.84 | F12: 53.67 | G12: 53.67 | H12: 54.75 | I12: 54.39 | J12: 54.4
A13: PI_100 | B13: mbar | C13: 1014.07 | D13: 1002.74 | E13: 1040.05 | F13: 1027.44 | G13: 1012.1 | H13: 1030.53 | I13: 1031.27 | J13: 1001.61
A14: PI_102 | B14: mbar | C14: 1019.19 | D14: 1005.78 | E14: 1048.13 | F14: 1032.3 | G14: 1020.73 | H14: 1038.75 | I14: 1041.48 | J14: 1010.21
A15: PI_103 | B15: mbar | C15: 1016.6 | D15: 1010.37 | E15: 1056.4 | F15: 1035.01 | G15: 1029 | H15: 1042.66 | I15: 1045.31 | J15: 1014.5
A16: PT_02 | B16: barg | C16: 0.9 | D16: 0.9 | E16: 0.9 | F16: 0.9 | G16: 0.9 | H16: 0.7 | I16: 0.7 | J16: 0.7
A17: PT_04 | B17: barg | C17: 0.89 | D17: 0.88 | E17: 0.88 | F17: 0.89 | G17: 0.88 | H17: 0.69 | I17: 0.68 | J17: 0.7
A18: PT11 | B18: L | C18: 6.48 | D18: 6.89 | E18: 6.97 | F18: 5.86 | G18: 6.6 | H18: 6.49 | I18: 6.78 | J18: 5.67
A19: QT_100 | B19: kg/l | C19: 1.069 | D19: 1.065 | E19: 1.053 | F19: 1.057 | G19: 1.069 | H19: 1.075 | I19: 1.071 | J19: 1.059
A20: QT_101 | B20: kg/l | C20: 1.091 | D20: 1.097 | E20: 1.102 | F20: 1.097 | G20: 1.092 | H20: 1.102 | I20: 1.096 | J20: 1.073
... A51: TV5 | B51: °C | C51: 43.26 | D51: 50.54 | E51: 49.37 | F51: 43.55 | G51: 47.16 | H51: 40.71 | I51: 41.86 | J51: 37.87
A52: Test | C52: 10 | D52: 55

Sheet SS case 1
A1: Timeline: | B1: Engineering
A2: Model server: | B2: ProcessModel
A4: Case: | B4: 1
A6: Fargevisning:
A7: Grønn: | B7: 0 | C7: 5
A8: Gul: | B8: 5 | C8: 10
A9: Rød: | B9: 10 | C9: 100
A11: TAG in literature | B11: Value from Appendix A | C11: TAG in model | D11: Data-tag in model | E11: SimulatedValue | F11: unit | G11: % deviation | H11: Comment
A12: SETPOINTS SET IN MCL
A13: FT06 | B13: =IFERROR(_xlfn.XLOOKUP(A13,'Appendix A'!A:A,'Appendix A'!C:C),"") -> 89.77 | C13: 00FIC001 | D13: 00FIC001:InternalSetpoint | E13: {=_xll.ReadKSpice(_xlfn.CONCAT("/",$B$1,"/",$B$2,"/",D13,"@V_Unit=",F13))} -> #N/A | F13: m3/h | G13: =100*(E13-B13)/B13 -> #N/A | H13: Gas Flow Rate
A14: FT_100 | B14: =IFERROR(_xlfn.XLOOKUP(A14,'Appendix A'!A:A,'Appendix A'!C:C),"") -> 166.93 | C14: 00FC001 | D14: 00FC001:InternalSetpoint | E14: {=_xll.ReadKSpice(_xlfn.CONCAT("/",$B$1,"/",$B$2,"/",D14,"@V_Unit=",F14))} -> #N/A | F14: kg/h | G14: =100*(E14-B14)/B14 -> #N/A | H14: Solvent Flow Rate Lean input
A15: TA08 | B15: =IFERROR(_xlfn.XLOOKUP(A15,'Appendix A'!A:A,'Appendix A'!C:C),"") -> 49.1 | C15: LeanMEA_inn | D15: LeanMEA_inn:InstructorTemperature | E15: {=_xll.ReadKSpice(_xlfn.CONCAT("/",$B$1,"/",$B$2,"/",D15,"@V_Unit=",F15))} -> #N/A | F15: degC | G15: =100*(E15-B15)/B15 -> #N/A | H15: Temperature Lean Solvent LeanMEA_inn
A16: TA08 | B16: =IFERROR(_xlfn.XLOOKUP(A16,'Appendix A'!A:A,'Appendix A'!C:C),"") -> 49.1 | C16: 02TIC002 | D16: 02TIC002:InternalSetpoint | E16: {=_xll.ReadKSpice(_xlfn.CONCAT("/",$B$1,"/",$B$2,"/",D16,"@V_Unit=",F16))} -> #N/A | F16: degC | G16: =100*(E16-B16)/B16 -> #N/A | H16: Temperature Lean Solvent LeanMEA_ut
A17: HE_04/05/06 | B17: =IFERROR(_xlfn.XLOOKUP(A17,'Appendix A'!A:A,'Appendix A'!C:C),"") -> 6.82 | C17: 02QIC001 | D17: 02QIC001:InternalSetpoint | E17: {=_xll.ReadKSpice(_xlfn.CONCAT("/",$B$1,"/",$B$2,"/",D17,"@V_Unit=",F17))} -> #N/A | F17: kW | G17: =100*(E17-B17)/B17 -> #N/A | H17: Reboiler Duty
A18: TAB | B18: =IFERROR(_xlfn.XLOOKUP(A18,'Appendix A'!A:A,'Appendix A'!C:C),"") -> 42.18 | C18: 00TIC000 | D18: 00TIC000:InternalSetpoint | E18: {=_xll.ReadKSpice(_xlfn.CONCAT("/",$B$1,"/",$B$2,"/",D18,"@V_Unit=",F18))} -> #N/A | F18: degC | G18: =100*(E18-B18)/B18 -> #N/A | H18: Absorber Inlet CO2 Temperature
B19: 0.3 | C19: LAL_IN | D19: LAL_IN:Output | E19: {=_xll.ReadKSpice(_xlfn.CONCAT("/",$B$1,"/",$B$2,"/",D19,"@V_Unit=",F19))} -> #N/A | F19: mol/mol | G19: =100*(E19-B19)/B19 -> #N/A | H19: CO2 Loading Lean input
A20: PI_100 | B20: =IFERROR(_xlfn.XLOOKUP(A20,'Appendix A'!A:A,'Appendix A'!C:C),"") -> 1014.07 | C20: 00PIC002 | D20: 00PIC002:InternalSetpoint | E20: {=_xll.ReadKSpice(_xlfn.CONCAT("/",$B$1,"/",$B$2,"/",D20,"@V_Unit=",F20))} -> #N/A | F20: mbara | G20: =100*(E20-B20)/B20 -> #N/A | H20: Pressure in absorber
A21: PT_02 | B21: =IFERROR(_xlfn.XLOOKUP(A21,'Appendix A'!A:A,'Appendix A'!C:C),"") -> 0.9 | C21: 04PIC001 | D21: 04PIC001:InternalSetpoint | E21: {=_xll.ReadKSpice(_xlfn.CONCAT("/",$B$1,"/",$B$2,"/",D21,"@V_Unit=",F21))} -> #N/A | F21: barg | G21: =100*(E21-B21)/B21 -> #N/A | H21: Pressure in reboiler
A22: TT_01 | B22: =IFERROR(_xlfn.XLOOKUP(A22,'Appendix A'!A:A,'Appendix A'!C:C),"") -> 30.65 | C22: 03TIC001 | D22: 03TIC001:InternalSetpoint | E22: {=_xll.ReadKSpice(_xlfn.CONCAT("/",$B$1,"/",$B$2,"/",D22,"@V_Unit=",F22))} -> #N/A | F22: degC | G22: =100*(E22-B22)/B22 -> #N/A | H22: EX03 cooling loop
A23: TT_02 | B23: =IFERROR(_xlfn.XLOOKUP(A23,'Appendix A'!A:A,'Appendix A'!C:C),"") -> 18.08 | C23: 04TIC001 | D23: 04TIC001:InternalSetpoint | E23: {=_xll.ReadKSpice(_xlfn.CONCAT("/",$B$1,"/",$B$2,"/",D23,"@V_Unit=",F23))} -> #N/A | F23: degC | G23: =100*(E23-B23)/B23 -> #N/A | H23: EX04 cooling loop
A25: FLOW INTO ABSORBER
A26: FT06 | B26: =IFERROR(_xlfn.XLOOKUP(A26,'Appendix A'!A:A,'Appendix A'!C:C),"") -> 89.77 | C26: 00FT001 | D26: 00FT001:MeasuredValue | E26: {=_xll.ReadKSpice(_xlfn.CONCAT("/",$B$1,"/",$B$2,"/",D26,"@V_Unit=",F26))} -> #N/A | F26: m3/h | G26: =100*(E26-B26)/B26 -> #N/A
A27: PI_103 | B27: =IFERROR(_xlfn.XLOOKUP(A27,'Appendix A'!A:A,'Appendix A'!C:C),"") -> 1016.6 | C27: 00PT001 | D27: 00PT001:MeasuredValue | E27: {=_xll.ReadKSpice(_xlfn.CONCAT("/",$B$1,"/",$B$2,"/",D27,"@V_Unit=",F27))} -> #N/A | F27: mbara | G27: =100*(E27-B27)/B27 -> #N/A
A28: TV5 | B28: =IFERROR(_xlfn.XLOOKUP(A28,'Appendix A'!A:A,'Appendix A'!C:C),"") -> 43.26 | C28: 00TAB000 | D28: 00TAB000:MeasuredValue | E28: {=_xll.ReadKSpice(_xlfn.CONCAT("/",$B$1,"/",$B$2,"/",D28,"@V_Unit=",F28))} -> #N/A | F28: degC | G28: =100*(E28-B28)/B28 -> #N/A
A29: FT_100 | B29: =IFERROR(_xlfn.XLOOKUP(A29,'Appendix A'!A:A,'Appendix A'!C:C),"") -> 166.93 | C29: 00FT003 | D29: 00FT003:MeasuredValue | E29: {=_xll.ReadKSpice(_xlfn.CONCAT("/",$B$1,"/",$B$2,"/",D29,"@V_Unit=",F29))} -> #N/A | F29: kg/h | G29: =100*(E29-B29)/B29 -> #N/A
A30: TA08 | B30: =IFERROR(_xlfn.XLOOKUP(A30,'Appendix A'!A:A,'Appendix A'!C:C),"") -> 49.1 | C30: LeanAmineInput | D30: LeanAmineInput:OutletStream.t | E30: {=_xll.ReadKSpice(_xlfn.CONCAT("/",$B$1,"/",$B$2,"/",D30,"@V_Unit=",F30))} -> #N/A | F30: degC | G30: =100*(E30-B30)/B30 -> #N/A | H30: Temperature Lean Solvent LeanMEA_inn
A31: TA08 | B31: =IFERROR(_xlfn.XLOOKUP(A31,'Appendix A'!A:A,'Appendix A'!C:C),"") -> 49.1 | C31: 02TT002 | D31: 02TT002:MeasuredValue | E31: {=_xll.ReadKSpice(_xlfn.CONCAT("/",$B$1,"/",$B$2,"/",D31,"@V_Unit=",F31))} -> #N/A | F31: degC | G31: =100*(E31-B31)/B31 -> #N/A | H31: Temperature Lean Solvent LeanMEA_ut
A33: ABSORBER
A34: CO2_IN | B34: =IFERROR(_xlfn.XLOOKUP(A34,'Appendix A'!A:A,'Appendix A'!C:C),"") -> 3.52 | C34: GasToAbsorber | D34: GasToAbsorber:OutputCompositionVector[4] | E34: {=_xll.ReadKSpice(_xlfn.CONCAT("/",$B$1,"/",$B$2,"/",D34,"@V_Unit=",F34))} -> #N/A | F34: % | G34: =100*(E34-B34)/B34 -> #N/A | H34: % CO2
A35: CO2_OUT (Gas) | B35: =IFERROR(_xlfn.XLOOKUP(A35,'Appendix A'!A:A,'Appendix A'!D:D),"") | C35: GasFromAbsorber | D35: GasFromAbsorber:OutputCompositionVector[4] | E35: {=_xll.ReadKSpice(_xlfn.CONCAT("/",$B$1,"/",$B$2,"/",D35,"@V_Unit=",F35))} -> #N/A | F35: % | H35: CO2 in gas form
A36: CO2_OUT (In MEA) | B36: =IFERROR(_xlfn.XLOOKUP(A36,'Appendix A'!A:A,'Appendix A'!D:D),"") | C36: GasFromAbsorber | D36: GasFromAbsorber:OutputCompositionVector[2] | E36: {=_xll.ReadKSpice(_xlfn.CONCAT("/",$B$1,"/",$B$2,"/",D36,"@V_Unit=",F36))} -> #N/A | F36: % | H36: CO2 in MEA
A37: CO2_OUT | B37: =IFERROR(_xlfn.XLOOKUP(A37,'Appendix A'!A:A,'Appendix A'!C:C),"") -> 0.29 | C37: GasFromAbsorber | E37: =E36+E35 -> #N/A | F37: % | G37: =100*(E37-B37)/B37 -> #N/A | H37: Combined CO2 % in treated gas
A38: PI_100 | B38: =IFERROR(_xlfn.XLOOKUP(A38,'Appendix A'!A:A,'Appendix A'!C:C),"") -> 1014.07 | C38: 00PI100 | D38: 00PI100:MeasuredValue | E38: {=_xll.ReadKSpice(_xlfn.CONCAT("/",$B$1,"/",$B$2,"/",D38,"@V_Unit=",F38))} -> #N/A | F38: mbara | G38: =100*(E38-B38)/B38 -> #N/A
A39: PI_102 | B39: =IFERROR(_xlfn.XLOOKUP(A39,'Appendix A'!A:A,'Appendix A'!C:C),"") -> 1019.19 | C39: 00PI102 | D39: 00PI102:MeasuredValue | E39: {=_xll.ReadKSpice(_xlfn.CONCAT("/",$B$1,"/",$B$2,"/",D39,"@V_Unit=",F39))} -> #N/A | F39: mbara | G39: =100*(E39-B39)/B39 -> #N/A
A40: TAB | B40: =IFERROR(_xlfn.XLOOKUP(A40,'Appendix A'!A:A,'Appendix A'!C:C),"") -> 42.18 | C40: 00TAB000 | D40: 00TAB000:MeasuredValue | E40: {=_xll.ReadKSpice(_xlfn.CONCAT("/",$B$1,"/",$B$2,"/",D40,"@V_Unit=",F40))} -> #N/A | F40: degC | G40: =100*(E40-B40)/B40 -> #N/A | H40: Lik TV5? Det er samme transpimmer i K-spice
A41: TA00 | B41: =IFERROR(_xlfn.XLOOKUP(A41,'Appendix A'!A:A,'Appendix A'!C:C),"") -> 45.14 | C41: 00TA000 | D41: 00TA000:MeasuredValue | E41: {=_xll.ReadKSpice(_xlfn.CONCAT("/",$B$1,"/",$B$2,"/",D41,"@V_Unit=",F41))} -> #N/A | F41: degC | G41: =100*(E41-B41)/B41 -> #N/A
A42: TA01 | B42: =IFERROR(_xlfn.XLOOKUP(A42,'Appendix A'!A:A,'Appendix A'!C:C),"") -> 46.62 | C42: 00TA001 | D42: 00TA001:MeasuredValue | E42: {=_xll.ReadKSpice(_xlfn.CONCAT("/",$B$1,"/",$B$2,"/",D42,"@V_Unit=",F42))} -> #N/A | F42: degC | G42: =100*(E42-B42)/B42 -> #N/A
A43: TA02 | B43: =IFERROR(_xlfn.XLOOKUP(A43,'Appendix A'!A:A,'Appendix A'!C:C),"") -> 49.38 | C43: 00TA002 | D43: 00TA002:MeasuredValue | E43: {=_xll.ReadKSpice(_xlfn.CONCAT("/",$B$1,"/",$B$2,"/",D43,"@V_Unit=",F43))} -> #N/A | F43: degC | G43: =100*(E43-B43)/B43 -> #N/A
A44: TA03 | B44: =IFERROR(_xlfn.XLOOKUP(A44,'Appendix A'!A:A,'Appendix A'!C:C),"") -> 50.97 | C44: 00TA003 | D44: 00TA003:MeasuredValue | E44: {=_xll.ReadKSpice(_xlfn.CONCAT("/",$B$1,"/",$B$2,"/",D44,"@V_Unit=",F44))} -> #N/A | F44: degC | G44: =100*(E44-B44)/B44 -> #N/A
A45: TA04 | B45: =IFERROR(_xlfn.XLOOKUP(A45,'Appendix A'!A:A,'Appendix A'!C:C),"") -> 52.49 | C45: 00TA004 | D45: 00TA004:MeasuredValue | E45: {=_xll.ReadKSpice(_xlfn.CONCAT("/",$B$1,"/",$B$2,"/",D45,"@V_Unit=",F45))} -> #N/A | F45: degC | G45: =100*(E45-B45)/B45 -> #N/A
...

Sheet SS case 1 (v19.5)
A1: Timeline: | B1: Engineering
A2: Model server: | B2: ProcessModel
A4: Case: | B4: 1
A6: Fargevisning:
A7: Grønn: | B7: 0 | C7: 5
A8: Gul: | B8: 5 | C8: 10
A9: Rød: | B9: 10 | C9: 100 | F9: GJ KPI avvik: | G9: {=AVERAGE(ABS(G101:G104))} -> 9.8841281
F10: Gj. Avvik: | G10: {=AVERAGE(ABS(G26:G31),ABS(G34),ABS(G37:G49),ABS(G52),ABS(G55),ABS(G57:G58),ABS(G61:G68),ABS(G71:G76),ABS(G79),ABS(G80),ABS(G83),ABS(G85),ABS(G88),ABS(G91),ABS(G101:G103))} -> 5.3414388
A11: TAG in literature | B11: Value from Appendix A | C11: TAG in model | D11: Data-tag in model | E11: SimulatedValue | F11: unit | G11: % deviation | H11: Comment
A12: SETPOINTS SET IN MCL
A13: FT06 | B13: 89.77 | C13: 00FIC001 | D13: 00FIC001:InternalSetpoint | E13: 89.77 | F13: m3/h | G13: 0 | H13: Gas Flow Rate
A14: FT_100 | B14: 166.93 | C14: 00FC001 | D14: 00FC001:InternalSetpoint | E14: 166.9 | F14: kg/h | G14: -0.017971605 | H14: Solvent Flow Rate Lean input
A15: TA08 | B15: 49.1 | C15: LeanMEA_inn | D15: LeanMEA_inn:InstructorTemperature | E15: 49.1 | F15: degC | G15: 4.3414016e-14 | H15: Temperature Lean Solvent LeanMEA_inn
A16: TA08 | B16: 49.1 | C16: 02TIC002 | D16: 02TIC002:InternalSetpoint | E16: 49.1 | F16: degC | G16: 4.3414016e-14 | H16: Temperature Lean Solvent LeanMEA_ut
A17: HE_04/05/06 | B17: 6.82 | C17: 02QIC001 | D17: 02QIC001:InternalSetpoint | E17: 6.8 | F17: kW | G17: -0.29325513 | H17: Reboiler Duty
A18: TAB | B18: 42.18 | C18: 00TIC000 | D18: 00TIC000:InternalSetpoint | E18: 42.18 | F18: degC | G18: 1.6845489e-14 | H18: Absorber Inlet CO2 Temperature
B19: 0.3 | C19: LAL_IN | D19: LAL_IN:Output | E19: 0.29999017 | F19: mol/mol | G19: -0.00327592 | H19: CO2 Loading Lean input
A20: PI_100 | B20: 1014.07 | C20: 00PIC002 | D20: 00PIC002:InternalSetpoint | E20: 1014.07 | F20: mbara | G20: 0 | H20: Pressure in absorber
A21: PT_02 | B21: 0.9 | C21: 04PIC001 | D21: 04PIC001:InternalSetpoint | E21: 0.9 | F21: barg | G21: 1.2335811e-14 | H21: Pressure in reboiler
A22: TT_01 | B22: 30.65 | C22: 03TIC001 | D22: 03TIC001:InternalSetpoint | E22: 30.65 | F22: degC | G22: -6.9547413e-14 | H22: EX03 cooling loop
A23: TT_02 | B23: 18.08 | C23: 04TIC001 | D23: 04TIC001:InternalSetpoint | E23: 18.08 | F23: degC | G23: -7.859986e-14 | H23: EX04 cooling loop
A25: FLOW INTO ABSORBER
A26: FT06 | B26: 89.77 | C26: 00FT001 | D26: 00FT001:MeasuredValue | E26: 89.77 | F26: m3/h | G26: 1.5949654e-08
A27: PI_103 | B27: 1016.6 | C27: 00PT001 | D27: 00PT001:MeasuredValue | E27: 1016.9171 | F27: mbara | G27: 0.03119264
A28: TV5 | B28: 43.26 | C28: 00TAB000 | D28: 00TAB000:MeasuredValue | E28: 42.18 | F28: degC | G28: -2.4965326
A29: FT_100 | B29: 166.93 | C29: 00FT003 | D29: 00FT003:MeasuredValue | E29: 166.9 | F29: kg/h | G29: -0.017971605
A30: TA08 | B30: 49.1 | C30: LeanAmineInput | D30: LeanAmineInput:OutletStream.t | E30: 49.105499 | F30: degC | G30: 0.011200039 | H30: Temperature Lean Solvent LeanMEA_inn
A31: TA08 | B31: 49.1 | C31: 02TT002 | D31: 02TT002:MeasuredValue | E31: 43.271168 | F31: degC | G31: -11.871349 | H31: Temperature Lean Solvent LeanMEA_ut
A33: ABSORBER
A34: CO2_IN | B34: 3.52 | C34: GasToAbsorber | D34: GasToAbsorber:OutputCompositionVector[4] | E34: 3.657213 | F34: % | G34: 3.8980954 | H34: % CO2
A35: CO2_OUT (Gas) | C35: GasFromAbsorber | D35: GasFromAbsorber:OutputCompositionVector[4] | E35: 0.12217625 | F35: % | H35: CO2 in gas form
A36: CO2_OUT (In MEA) | C36: GasFromAbsorber | D36: GasFromAbsorber:OutputCompositionVector[2] | E36: 0.066244726 | F36: % | H36: CO2 in MEA
A37: CO2_OUT | B37: 0.29 | C37: GasFromAbsorber | E37: 0.18842097 | F37: % | G37: -35.027251 | H37: Combined CO2 % in treated gas
A38: PI_100 | B38: 1014.07 | C38: 00PI100 | D38: 00PI100:MeasuredValue | E38: 1014.07 | F38: mbara | G38: -4.689394e-08
A39: PI_102 | B39: 1019.19 | C39: 00PI102 | D39: 00PI102:MeasuredValue | E39: 1016.7288 | F39: mbara | G39: -0.24148628
A40: TAB | B40: 42.18 | C40: 00TAB000 | D40: 00TAB000:MeasuredValue | E40: 42.18 | F40: degC | G40: -3.5656847e-10 | H40: Lik TV5? Det er samme transpimmer i K-spice
A41: TA00 | B41: 45.14 | C41: 00TA000 | D41: 00TA000:MeasuredValue | E41: 42.885413 | F41: degC | G41: -4.9946555
A42: TA01 | B42: 46.62 | C42: 00TA001 | D42: 00TA001:MeasuredValue | E42: 42.857455 | F42: degC | G42: -8.0706679
A43: TA02 | B43: 49.38 | C43: 00TA002 | D43: 00TA002:MeasuredValue | E43: 50.898921 | F43: degC | G43: 3.0759843
A44: TA03 | B44: 50.97 | C44: 00TA003 | D44: 00TA003:MeasuredValue | E44: 51.254026 | F44: degC | G44: 0.55724169
...

Sheet SS case 2
A1: Timeline: | B1: Engineering
A2: Model server: | B2: ProcessModel
A4: Case: | B4: 2
A6: Fargevisning:
A7: Grønn: | B7: 0 | C7: 5
A8: Gul: | B8: 5 | C8: 10
A9: Rød: | B9: 10 | C9: 100
A11: TAG in literature | B11: Value from Appendix A | C11: TAG in model | D11: Data-tag in model | E11: SimulatedValue | F11: unit | G11: % deviation | H11: Comment
A12: SETPOINTS SET IN MCL
A13: FT06 | B13: =IFERROR(_xlfn.XLOOKUP(A13,'Appendix A'!A:A,'Appendix A'!D:D),"") -> 90.09 | C13: 00FIC001 | D13: 00FIC001:InternalSetpoint | E13: {=_xll.ReadKSpice(_xlfn.CONCAT("/",$B$1,"/",$B$2,"/",D13,"@V_Unit=",F13))} -> #N/A | F13: m3/h | G13: =100*(E13-B13)/B13 -> #N/A | H13: Gas Flow Rate
A14: FT_100 | B14: =IFERROR(_xlfn.XLOOKUP(A14,'Appendix A'!A:A,'Appendix A'!D:D),"") -> 172.33 | C14: 00FC001 | D14: 00FC001:InternalSetpoint | E14: {=_xll.ReadKSpice(_xlfn.CONCAT("/",$B$1,"/",$B$2,"/",D14,"@V_Unit=",F14))} -> #N/A | F14: kg/h | G14: =100*(E14-B14)/B14 -> #N/A | H14: Solvent Flow Rate Lean input
A15: TA08 | B15: =IFERROR(_xlfn.XLOOKUP(A15,'Appendix A'!A:A,'Appendix A'!D:D),"") -> 58.31 | C15: LeanMEA_inn | D15: LeanMEA_inn:InstructorTemperature | E15: {=_xll.ReadKSpice(_xlfn.CONCAT("/",$B$1,"/",$B$2,"/",D15,"@V_Unit=",F15))} -> #N/A | F15: degC | G15: =100*(E15-B15)/B15 -> #N/A | H15: Temperature Lean Solvent LeanMEA_inn
A16: TA08 | B16: =IFERROR(_xlfn.XLOOKUP(A16,'Appendix A'!A:A,'Appendix A'!D:D),"") -> 58.31 | C16: 02TIC002 | D16: 02TIC002:InternalSetpoint | E16: {=_xll.ReadKSpice(_xlfn.CONCAT("/",$B$1,"/",$B$2,"/",D16,"@V_Unit=",F16))} -> #N/A | F16: degC | G16: =100*(E16-B16)/B16 -> #N/A | H16: Temperature Lean Solvent LeanMEA_ut
A17: HE_04/05/06 | B17: =IFERROR(_xlfn.XLOOKUP(A17,'Appendix A'!A:A,'Appendix A'!D:D),"") -> 9.23 | C17: 02QIC001 | D17: 02QIC001:InternalSetpoint | E17: {=_xll.ReadKSpice(_xlfn.CONCAT("/",$B$1,"/",$B$2,"/",D17,"@V_Unit=",F17))} -> #N/A | F17: kW | G17: =100*(E17-B17)/B17 -> #N/A | H17: Reboiler Duty
A18: TAB | B18: =IFERROR(_xlfn.XLOOKUP(A18,'Appendix A'!A:A,'Appendix A'!D:D),"") -> 49.24 | C18: 00TIC000 | D18: 00TIC000:InternalSetpoint | E18: {=_xll.ReadKSpice(_xlfn.CONCAT("/",$B$1,"/",$B$2,"/",D18,"@V_Unit=",F18))} -> #N/A | F18: degC | G18: =100*(E18-B18)/B18 -> #N/A | H18: Absorber Inlet CO2 Temperature
B19: 0.26 | C19: LAL_IN | D19: LAL_IN:Output | E19: {=_xll.ReadKSpice(_xlfn.CONCAT("/",$B$1,"/",$B$2,"/",D19,"@V_Unit=",F19))} -> #N/A | F19: mol/mol | G19: =100*(E19-B19)/B19 -> #N/A | H19: CO2 Loading Lean input
A20: PI_100 | B20: =IFERROR(_xlfn.XLOOKUP(A20,'Appendix A'!A:A,'Appendix A'!D:D),"") -> 1002.74 | C20: 00PIC002 | D20: 00PIC002:InternalSetpoint | E20: {=_xll.ReadKSpice(_xlfn.CONCAT("/",$B$1,"/",$B$2,"/",D20,"@V_Unit=",F20))} -> #N/A | F20: mbara | G20: =100*(E20-B20)/B20 -> #N/A | H20: Pressure in absorber
A21: PT_02 | B21: =IFERROR(_xlfn.XLOOKUP(A21,'Appendix A'!A:A,'Appendix A'!D:D),"") -> 0.9 | C21: 04PIC001 | D21: 04PIC001:InternalSetpoint | E21: {=_xll.ReadKSpice(_xlfn.CONCAT("/",$B$1,"/",$B$2,"/",D21,"@V_Unit=",F21))} -> #N/A | F21: barg | G21: =100*(E21-B21)/B21 -> #N/A | H21: Pressure in reboiler
A22: TT_01 | B22: =IFERROR(_xlfn.XLOOKUP(A22,'Appendix A'!A:A,'Appendix A'!D:D),"") -> 30.64 | C22: 03TIC001 | D22: 03TIC001:InternalSetpoint | E22: {=_xll.ReadKSpice(_xlfn.CONCAT("/",$B$1,"/",$B$2,"/",D22,"@V_Unit=",F22))} -> #N/A | F22: degC | G22: =100*(E22-B22)/B22 -> #N/A | H22: EX03 cooling loop
A23: TT_02 | B23: =IFERROR(_xlfn.XLOOKUP(A23,'Appendix A'!A:A,'Appendix A'!D:D),"") -> 25.01 | C23: 04TIC001 | D23: 04TIC001:InternalSetpoint | E23: {=_xll.ReadKSpice(_xlfn.CONCAT("/",$B$1,"/",$B$2,"/",D23,"@V_Unit=",F23))} -> #N/A | F23: degC | G23: =100*(E23-B23)/B23 -> #N/A | H23: EX04 cooling loop
A25: FLOW INTO ABSORBER
A26: FT06 | B26: =IFERROR(_xlfn.XLOOKUP(A26,'Appendix A'!A:A,'Appendix A'!D:D),"") -> 90.09 | C26: 00FT001 | D26: 00FT001:MeasuredValue | E26: {=_xll.ReadKSpice(_xlfn.CONCAT("/",$B$1,"/",$B$2,"/",D26,"@V_Unit=",F26))} -> #N/A | F26: m3/h | G26: =100*(E26-B26)/B26 -> #N/A
A27: PI_103 | B27: =IFERROR(_xlfn.XLOOKUP(A27,'Appendix A'!A:A,'Appendix A'!D:D),"") -> 1010.37 | C27: 00PT001 | D27: 00PT001:MeasuredValue | E27: {=_xll.ReadKSpice(_xlfn.CONCAT("/",$B$1,"/",$B$2,"/",D27,"@V_Unit=",F27))} -> #N/A | F27: mbara | G27: =100*(E27-B27)/B27 -> #N/A
A28: TV5 | B28: =IFERROR(_xlfn.XLOOKUP(A28,'Appendix A'!A:A,'Appendix A'!D:D),"") -> 50.54 | C28: 00TAB000 | D28: 00TAB000:MeasuredValue | E28: {=_xll.ReadKSpice(_xlfn.CONCAT("/",$B$1,"/",$B$2,"/",D28,"@V_Unit=",F28))} -> #N/A | F28: degC | G28: =100*(E28-B28)/B28 -> #N/A
A29: FT_100 | B29: =IFERROR(_xlfn.XLOOKUP(A29,'Appendix A'!A:A,'Appendix A'!D:D),"") -> 172.33 | C29: 00FT003 | D29: 00FT003:MeasuredValue | E29: {=_xll.ReadKSpice(_xlfn.CONCAT("/",$B$1,"/",$B$2,"/",D29,"@V_Unit=",F29))} -> #N/A | F29: kg/h | G29: =100*(E29-B29)/B29 -> #N/A
A30: TA08 | B30: =IFERROR(_xlfn.XLOOKUP(A30,'Appendix A'!A:A,'Appendix A'!D:D),"") -> 58.31 | C30: LeanAmineInput | D30: LeanAmineInput:OutletStream.t | E30: {=_xll.ReadKSpice(_xlfn.CONCAT("/",$B$1,"/",$B$2,"/",D30,"@V_Unit=",F30))} -> #N/A | F30: degC | G30: =100*(E30-B30)/B30 -> #N/A | H30: Temperature Lean Solvent LeanMEA_inn
A31: TA08 | B31: =IFERROR(_xlfn.XLOOKUP(A31,'Appendix A'!A:A,'Appendix A'!D:D),"") -> 58.31 | C31: 02TT002 | D31: 02TT002:MeasuredValue | E31: {=_xll.ReadKSpice(_xlfn.CONCAT("/",$B$1,"/",$B$2,"/",D31,"@V_Unit=",F31))} -> #N/A | F31: degC | G31: =100*(E31-B31)/B31 -> #N/A | H31: Temperature Lean Solvent LeanMEA_ut
A33: ABSORBER
A34: CO2_IN | B34: =IFERROR(_xlfn.XLOOKUP(A34,'Appendix A'!A:A,'Appendix A'!D:D),"") -> 6.77 | C34: GasToAbsorber | D34: GasToAbsorber:OutputCompositionVector[4] | E34: {=_xll.ReadKSpice(_xlfn.CONCAT("/",$B$1,"/",$B$2,"/",D34,"@V_Unit=",F34))} -> #N/A | F34: % | G34: =100*(E34-B34)/B34 -> #N/A | H34: % CO2
A35: CO2_OUT (Gas) | B35: =IFERROR(_xlfn.XLOOKUP(A35,'Appendix A'!A:A,'Appendix A'!D:D),"") | C35: GasFromAbsorber | D35: GasFromAbsorber:OutputCompositionVector[4] | E35: {=_xll.ReadKSpice(_xlfn.CONCAT("/",$B$1,"/",$B$2,"/",D35,"@V_Unit=",F35))} -> #N/A | F35: % | H35: CO2 in gas form
A36: CO2_OUT (In MEA) | B36: =IFERROR(_xlfn.XLOOKUP(A36,'Appendix A'!A:A,'Appendix A'!D:D),"") | C36: GasFromAbsorber | D36: GasFromAbsorber:OutputCompositionVector[2] | E36: {=_xll.ReadKSpice(_xlfn.CONCAT("/",$B$1,"/",$B$2,"/",D36,"@V_Unit=",F36))} -> #N/A | F36: % | H36: CO2 in MEA
A37: CO2_OUT | B37: =IFERROR(_xlfn.XLOOKUP(A37,'Appendix A'!A:A,'Appendix A'!D:D),"") -> 1.19 | C37: GasFromAbsorber | E37: =E36+E35 -> #N/A | F37: % | G37: =100*(E37-B37)/B37 -> #N/A | H37: Combined CO2 % in treated gas
A38: PI_100 | B38: =IFERROR(_xlfn.XLOOKUP(A38,'Appendix A'!A:A,'Appendix A'!D:D),"") -> 1002.74 | C38: 00PI100 | D38: 00PI100:MeasuredValue | E38: {=_xll.ReadKSpice(_xlfn.CONCAT("/",$B$1,"/",$B$2,"/",D38,"@V_Unit=",F38))} -> #N/A | F38: mbara | G38: =100*(E38-B38)/B38 -> #N/A
A39: PI_102 | B39: =IFERROR(_xlfn.XLOOKUP(A39,'Appendix A'!A:A,'Appendix A'!D:D),"") -> 1005.78 | C39: 00PI102 | D39: 00PI102:MeasuredValue | E39: {=_xll.ReadKSpice(_xlfn.CONCAT("/",$B$1,"/",$B$2,"/",D39,"@V_Unit=",F39))} -> #N/A | F39: mbara | G39: =100*(E39-B39)/B39 -> #N/A
A40: TAB | B40: =IFERROR(_xlfn.XLOOKUP(A40,'Appendix A'!A:A,'Appendix A'!D:D),"") -> 49.24 | C40: 00TAB000 | D40: 00TAB000:MeasuredValue | E40: {=_xll.ReadKSpice(_xlfn.CONCAT("/",$B$1,"/",$B$2,"/",D40,"@V_Unit=",F40))} -> #N/A | F40: degC | G40: =100*(E40-B40)/B40 -> #N/A | H40: Lik TV5? Det er samme transpimmer i K-spice
A41: TA00 | B41: =IFERROR(_xlfn.XLOOKUP(A41,'Appendix A'!A:A,'Appendix A'!D:D),"") -> 51.61 | C41: 00TA000 | D41: 00TA000:MeasuredValue | E41: {=_xll.ReadKSpice(_xlfn.CONCAT("/",$B$1,"/",$B$2,"/",D41,"@V_Unit=",F41))} -> #N/A | F41: degC | G41: =100*(E41-B41)/B41 -> #N/A
A42: TA01 | B42: =IFERROR(_xlfn.XLOOKUP(A42,'Appendix A'!A:A,'Appendix A'!D:D),"") -> 52.68 | C42: 00TA001 | D42: 00TA001:MeasuredValue | E42: {=_xll.ReadKSpice(_xlfn.CONCAT("/",$B$1,"/",$B$2,"/",D42,"@V_Unit=",F42))} -> #N/A | F42: degC | G42: =100*(E42-B42)/B42 -> #N/A
A43: TA02 | B43: =IFERROR(_xlfn.XLOOKUP(A43,'Appendix A'!A:A,'Appendix A'!D:D),"") -> 53.57 | C43: 00TA002 | D43: 00TA002:MeasuredValue | E43: {=_xll.ReadKSpice(_xlfn.CONCAT("/",$B$1,"/",$B$2,"/",D43,"@V_Unit=",F43))} -> #N/A | F43: degC | G43: =100*(E43-B43)/B43 -> #N/A
A44: TA03 | B44: =IFERROR(_xlfn.XLOOKUP(A44,'Appendix A'!A:A,'Appendix A'!D:D),"") -> 54.13 | C44: 00TA003 | D44: 00TA003:MeasuredValue | E44: {=_xll.ReadKSpice(_xlfn.CONCAT("/",$B$1,"/",$B$2,"/",D44,"@V_Unit=",F44))} -> #N/A | F44: degC | G44: =100*(E44-B44)/B44 -> #N/A
A45: TA04 | B45: =IFERROR(_xlfn.XLOOKUP(A45,'Appendix A'!A:A,'Appendix A'!D:D),"") -> 55.1 | C45: 00TA004 | D45: 00TA004:MeasuredValue | E45: {=_xll.ReadKSpice(_xlfn.CONCAT("/",$B$1,"/",$B$2,"/",D45,"@V_Unit=",F45))} -> #N/A | F45: degC | G45: =100*(E45-B45)/B45 -> #N/A
...

Sheet SS case 2 (v19.5)
A1: Timeline: | B1: Engineering
A2: Model server: | B2: ProcessModel
A4: Case: | B4: 2
A6: Fargevisning:
A7: Grønn: | B7: 0 | C7: 5
A8: Gul: | B8: 5 | C8: 10
A9: Rød: | B9: 10 | C9: 100 | F9: GJ KPI avvik: | G9: {=AVERAGE(ABS(G101:G104))} -> 8.2608676
F10: Gj. Avvik: | G10: {=AVERAGE(ABS(G26:G31),ABS(G34),ABS(G37:G49),ABS(G52),ABS(G55),ABS(G57:G58),ABS(G61:G68),ABS(G71:G76),ABS(G79),ABS(G80),ABS(G83),ABS(G85),ABS(G88),ABS(G91),ABS(G101:G103))} -> 9.0133989
A11: TAG in literature | B11: Value from Appendix A | C11: TAG in model | D11: Data-tag in model | E11: SimulatedValue | F11: unit | G11: % deviation | H11: Comment
A12: SETPOINTS SET IN MCL
A13: FT06 | B13: 90.09 | C13: 00FIC001 | D13: 00FIC001:InternalSetpoint | E13: 90.09 | F13: m3/h | G13: 0 | H13: Gas Flow Rate
A14: FT_100 | B14: 172.33 | C14: 00FC001 | D14: 00FC001:InternalSetpoint | E14: 172.3 | F14: kg/h | G14: -0.017408461 | H14: Solvent Flow Rate Lean input
A15: TA08 | B15: 58.31 | C15: LeanMEA_inn | D15: LeanMEA_inn:InstructorTemperature | E15: 58.31 | F15: degC | G15: 0 | H15: Temperature Lean Solvent LeanMEA_inn
A16: TA08 | B16: 58.31 | C16: 02TIC002 | D16: 02TIC002:InternalSetpoint | E16: 58.31 | F16: degC | G16: 0 | H16: Temperature Lean Solvent LeanMEA_ut
A17: HE_04/05/06 | B17: 9.23 | C17: 02QIC001 | D17: 02QIC001:InternalSetpoint | E17: 9.2 | F17: kW | G17: -0.32502709 | H17: Reboiler Duty
A18: TAB | B18: 49.24 | C18: 00TIC000 | D18: 00TIC000:InternalSetpoint | E18: 49.24 | F18: degC | G18: 1.4430194e-14 | H18: Absorber Inlet CO2 Temperature
B19: 0.26 | C19: LAL_IN | D19: LAL_IN:Output | E19: 0.25998231 | F19: mol/mol | G19: -0.0068051047 | H19: CO2 Loading Lean input
A20: PI_100 | B20: 1002.74 | C20: 00PIC002 | D20: 00PIC002:InternalSetpoint | E20: 1002.74 | F20: mbara | G20: 0 | H20: Pressure in absorber
A21: PT_02 | B21: 0.9 | C21: 04PIC001 | D21: 04PIC001:InternalSetpoint | E21: 0.9 | F21: barg | G21: 1.2335811e-14 | H21: Pressure in reboiler
A22: TT_01 | B22: 30.64 | C22: 03TIC001 | D22: 03TIC001:InternalSetpoint | E22: 30.64 | F22: degC | G22: -4.6380074e-14 | H22: EX03 cooling loop
A23: TT_02 | B23: 25.01 | C23: 04TIC001 | D23: 04TIC001:InternalSetpoint | E23: 25.01 | F23: degC | G23: -4.2615518e-14 | H23: EX04 cooling loop
A25: FLOW INTO ABSORBER
A26: FT06 | B26: 90.09 | C26: 00FT001 | D26: 00FT001:MeasuredValue | E26: 90.09 | F26: m3/h | G26: -1.7117542e-09
A27: PI_103 | B27: 1010.37 | C27: 00PT001 | D27: 00PT001:MeasuredValue | E27: 1016.5625 | F27: mbara | G27: 0.61288942
A28: TV5 | B28: 50.54 | C28: 00TAB000 | D28: 00TAB000:MeasuredValue | E28: 49.24 | F28: degC | G28: -2.57222
A29: FT_100 | B29: 172.33 | C29: 00FT003 | D29: 00FT003:MeasuredValue | E29: 172.3 | F29: kg/h | G29: -0.017408459
A30: TA08 | B30: 58.31 | C30: LeanAmineInput | D30: LeanAmineInput:OutletStream.t | E30: 58.315152 | F30: degC | G30: 0.0088348072 | H30: Temperature Lean Solvent LeanMEA_inn
A31: TA08 | B31: 58.31 | C31: 02TT002 | D31: 02TT002:MeasuredValue | E31: 36.510768 | F31: degC | G31: -37.385066 | H31: Temperature Lean Solvent LeanMEA_ut
A33: ABSORBER
A34: CO2_IN | B34: 6.77 | C34: GasToAbsorber | D34: GasToAbsorber:OutputCompositionVector[4] | E34: 7.07 | F34: % | G34: 4.4313146 | H34: % CO2
A35: CO2_OUT (Gas) | C35: GasFromAbsorber | D35: GasFromAbsorber:OutputCompositionVector[4] | E35: 0.86044665 | F35: % | H35: CO2 in gas form
A36: CO2_OUT (In MEA) | C36: GasFromAbsorber | D36: GasFromAbsorber:OutputCompositionVector[2] | E36: 0.15441535 | F36: % | H36: CO2 in MEA
A37: CO2_OUT | B37: 1.19 | C37: GasFromAbsorber | E37: 1.014862 | F37: % | G37: -14.717479 | H37: Combined CO2 % in treated gas
A38: PI_100 | B38: 1002.74 | C38: 00PI100 | D38: 00PI100:MeasuredValue | E38: 1013.6799 | F38: mbara | G38: 1.0909961
A39: PI_102 | B39: 1005.78 | C39: 00PI102 | D39: 00PI102:MeasuredValue | E39: 1016.3788 | F39: mbara | G39: 1.0537923
A40: TAB | B40: 49.24 | C40: 00TAB000 | D40: 00TAB000:MeasuredValue | E40: 49.24 | F40: degC | G40: 2.8990259e-11 | H40: Lik TV5? Det er samme transpimmer i K-spice
A41: TA00 | B41: 51.61 | C41: 00TA000 | D41: 00TA000:MeasuredValue | E41: 36.207834 | F41: degC | G41: -29.843375
A42: TA01 | B42: 52.68 | C42: 00TA001 | D42: 00TA001:MeasuredValue | E42: 36.180429 | F42: degC | G42: -31.32037
A43: TA02 | B43: 53.57 | C43: 00TA002 | D43: 00TA002:MeasuredValue | E43: 39.844703 | F43: degC | G43: -25.621237
A44: TA03 | B44: 54.13 | C44: 00TA003 | D44: 00TA003:MeasuredValue | E44: 42.652794 | F44: degC | G44: -21.203041
...

Sheet SS case 3
A1: Timeline: | B1: Engineering
A2: Model server: | B2: ProcessModel
A4: Case: | B4: 3
A6: Fargevisning:
A7: Grønn: | B7: 0 | C7: 5
A8: Gul: | B8: 5 | C8: 10
A9: Rød: | B9: 10 | C9: 100
A11: TAG in literature | B11: Value from Appendix A | C11: TAG in model | D11: Data-tag in model | E11: SimulatedValue | F11: unit | G11: % deviation | H11: Comment
A12: SETPOINTS SET IN MCL
A13: FT06 | B13: =IFERROR(_xlfn.XLOOKUP(A13,'Appendix A'!A:A,'Appendix A'!E:E),"") -> 127.02 | C13: 00FIC001 | D13: 00FIC001:InternalSetpoint | E13: {=_xll.ReadKSpice(_xlfn.CONCAT("/",$B$1,"/",$B$2,"/",D13,"@V_Unit=",F13))} -> #N/A | F13: m3/h | G13: =100*(E13-B13)/B13 -> #N/A | H13: Gas Flow Rate
A14: FT_100 | B14: =IFERROR(_xlfn.XLOOKUP(A14,'Appendix A'!A:A,'Appendix A'!E:E),"") -> 152.07 | C14: 00FC001 | D14: 00FC001:InternalSetpoint | E14: {=_xll.ReadKSpice(_xlfn.CONCAT("/",$B$1,"/",$B$2,"/",D14,"@V_Unit=",F14))} -> #N/A | F14: kg/h | G14: =100*(E14-B14)/B14 -> #N/A | H14: Solvent Flow Rate Lean input
A15: TA08 | B15: =IFERROR(_xlfn.XLOOKUP(A15,'Appendix A'!A:A,'Appendix A'!E:E),"") -> 57.95 | C15: LeanMEA_inn | D15: LeanMEA_inn:InstructorTemperature | E15: {=_xll.ReadKSpice(_xlfn.CONCAT("/",$B$1,"/",$B$2,"/",D15,"@V_Unit=",F15))} -> #N/A | F15: degC | G15: =100*(E15-B15)/B15 -> #N/A | H15: Temperature Lean Solvent LeanMEA_inn
A16: TA08 | B16: =IFERROR(_xlfn.XLOOKUP(A16,'Appendix A'!A:A,'Appendix A'!E:E),"") -> 57.95 | C16: 02TIC002 | D16: 02TIC002:InternalSetpoint | E16: {=_xll.ReadKSpice(_xlfn.CONCAT("/",$B$1,"/",$B$2,"/",D16,"@V_Unit=",F16))} -> #N/A | F16: degC | G16: =100*(E16-B16)/B16 -> #N/A | H16: Temperature Lean Solvent LeanMEA_ut
A17: HE_04/05/06 | B17: =IFERROR(_xlfn.XLOOKUP(A17,'Appendix A'!A:A,'Appendix A'!E:E),"") -> 10.02 | C17: 02QIC001 | D17: 02QIC001:InternalSetpoint | E17: {=_xll.ReadKSpice(_xlfn.CONCAT("/",$B$1,"/",$B$2,"/",D17,"@V_Unit=",F17))} -> #N/A | F17: kW | G17: =100*(E17-B17)/B17 -> #N/A | H17: Reboiler Duty
A18: TAB | B18: =IFERROR(_xlfn.XLOOKUP(A18,'Appendix A'!A:A,'Appendix A'!E:E),"") -> 46.68 | C18: 00TIC000 | D18: 00TIC000:InternalSetpoint | E18: {=_xll.ReadKSpice(_xlfn.CONCAT("/",$B$1,"/",$B$2,"/",D18,"@V_Unit=",F18))} -> #N/A | F18: degC | G18: =100*(E18-B18)/B18 -> #N/A | H18: Absorber Inlet CO2 Temperature
B19: 0.22 | C19: LAL_IN | D19: LAL_IN:Output | E19: {=_xll.ReadKSpice(_xlfn.CONCAT("/",$B$1,"/",$B$2,"/",D19,"@V_Unit=",F19))} -> #N/A | F19: mol/mol | G19: =100*(E19-B19)/B19 -> #N/A | H19: CO2 Loading Lean input
A20: PI_100 | B20: =IFERROR(_xlfn.XLOOKUP(A20,'Appendix A'!A:A,'Appendix A'!E:E),"") -> 1040.05 | C20: 00PIC002 | D20: 00PIC002:InternalSetpoint | E20: {=_xll.ReadKSpice(_xlfn.CONCAT("/",$B$1,"/",$B$2,"/",D20,"@V_Unit=",F20))} -> #N/A | F20: mbara | G20: =100*(E20-B20)/B20 -> #N/A | H20: Pressure in absorber
A21: PT_02 | B21: =IFERROR(_xlfn.XLOOKUP(A21,'Appendix A'!A:A,'Appendix A'!E:E),"") -> 0.9 | C21: 04PIC001 | D21: 04PIC001:InternalSetpoint | E21: {=_xll.ReadKSpice(_xlfn.CONCAT("/",$B$1,"/",$B$2,"/",D21,"@V_Unit=",F21))} -> #N/A | F21: barg | G21: =100*(E21-B21)/B21 -> #N/A | H21: Pressure in reboiler
A22: TT_01 | B22: =IFERROR(_xlfn.XLOOKUP(A22,'Appendix A'!A:A,'Appendix A'!E:E),"") -> 30.74 | C22: 03TIC001 | D22: 03TIC001:InternalSetpoint | E22: {=_xll.ReadKSpice(_xlfn.CONCAT("/",$B$1,"/",$B$2,"/",D22,"@V_Unit=",F22))} -> #N/A | F22: degC | G22: =100*(E22-B22)/B22 -> #N/A | H22: EX03 cooling loop
A23: TT_02 | B23: =IFERROR(_xlfn.XLOOKUP(A23,'Appendix A'!A:A,'Appendix A'!E:E),"") -> 29.4 | C23: 04TIC001 | D23: 04TIC001:InternalSetpoint | E23: {=_xll.ReadKSpice(_xlfn.CONCAT("/",$B$1,"/",$B$2,"/",D23,"@V_Unit=",F23))} -> #N/A | F23: degC | G23: =100*(E23-B23)/B23 -> #N/A | H23: EX04 cooling loop
A25: FLOW INTO ABSORBER
A26: FT06 | B26: =IFERROR(_xlfn.XLOOKUP(A26,'Appendix A'!A:A,'Appendix A'!E:E),"") -> 127.02 | C26: 00FT001 | D26: 00FT001:MeasuredValue | E26: {=_xll.ReadKSpice(_xlfn.CONCAT("/",$B$1,"/",$B$2,"/",D26,"@V_Unit=",F26))} -> #N/A | F26: m3/h | G26: =100*(E26-B26)/B26 -> #N/A
A27: PI_103 | B27: =IFERROR(_xlfn.XLOOKUP(A27,'Appendix A'!A:A,'Appendix A'!E:E),"") -> 1056.4 | C27: 00PT001 | D27: 00PT001:MeasuredValue | E27: {=_xll.ReadKSpice(_xlfn.CONCAT("/",$B$1,"/",$B$2,"/",D27,"@V_Unit=",F27))} -> #N/A | F27: mbara | G27: =100*(E27-B27)/B27 -> #N/A
A28: TV5 | B28: =IFERROR(_xlfn.XLOOKUP(A28,'Appendix A'!A:A,'Appendix A'!E:E),"") -> 49.37 | C28: 00TAB000 | D28: 00TAB000:MeasuredValue | E28: {=_xll.ReadKSpice(_xlfn.CONCAT("/",$B$1,"/",$B$2,"/",D28,"@V_Unit=",F28))} -> #N/A | F28: degC | G28: =100*(E28-B28)/B28 -> #N/A
A29: FT_100 | B29: =IFERROR(_xlfn.XLOOKUP(A29,'Appendix A'!A:A,'Appendix A'!E:E),"") -> 152.07 | C29: 00FT003 | D29: 00FT003:MeasuredValue | E29: {=_xll.ReadKSpice(_xlfn.CONCAT("/",$B$1,"/",$B$2,"/",D29,"@V_Unit=",F29))} -> #N/A | F29: kg/h | G29: =100*(E29-B29)/B29 -> #N/A
A30: TA08 | B30: =IFERROR(_xlfn.XLOOKUP(A30,'Appendix A'!A:A,'Appendix A'!E:E),"") -> 57.95 | C30: LeanAmineInput | D30: LeanAmineInput:OutletStream.t | E30: {=_xll.ReadKSpice(_xlfn.CONCAT("/",$B$1,"/",$B$2,"/",D30,"@V_Unit=",F30))} -> #N/A | F30: degC | G30: =100*(E30-B30)/B30 -> #N/A | H30: Temperature Lean Solvent LeanMEA_inn
A31: TA08 | B31: =IFERROR(_xlfn.XLOOKUP(A31,'Appendix A'!A:A,'Appendix A'!E:E),"") -> 57.95 | C31: 02TT002 | D31: 02TT002:MeasuredValue | E31: {=_xll.ReadKSpice(_xlfn.CONCAT("/",$B$1,"/",$B$2,"/",D31,"@V_Unit=",F31))} -> #N/A | F31: degC | G31: =100*(E31-B31)/B31 -> #N/A | H31: Temperature Lean Solvent LeanMEA_ut
A33: ABSORBER
A34: CO2_IN | B34: =IFERROR(_xlfn.XLOOKUP(A34,'Appendix A'!A:A,'Appendix A'!E:E),"") -> 7.41 | C34: GasToAbsorber | D34: GasToAbsorber:OutputCompositionVector[4] | E34: {=_xll.ReadKSpice(_xlfn.CONCAT("/",$B$1,"/",$B$2,"/",D34,"@V_Unit=",F34))} -> #N/A | F34: % | G34: =100*(E34-B34)/B34 -> #N/A | H34: % CO2
A35: CO2_OUT (Gas) | B35: =IFERROR(_xlfn.XLOOKUP(A35,'Appendix A'!A:A,'Appendix A'!D:D),"") | C35: GasFromAbsorber | D35: GasFromAbsorber:OutputCompositionVector[4] | E35: {=_xll.ReadKSpice(_xlfn.CONCAT("/",$B$1,"/",$B$2,"/",D35,"@V_Unit=",F35))} -> #N/A | F35: % | H35: CO2 in gas form
A36: CO2_OUT (In MEA) | B36: =IFERROR(_xlfn.XLOOKUP(A36,'Appendix A'!A:A,'Appendix A'!D:D),"") | C36: GasFromAbsorber | D36: GasFromAbsorber:OutputCompositionVector[2] | E36: {=_xll.ReadKSpice(_xlfn.CONCAT("/",$B$1,"/",$B$2,"/",D36,"@V_Unit=",F36))} -> #N/A | F36: % | H36: CO2 in MEA
A37: CO2_OUT | B37: =IFERROR(_xlfn.XLOOKUP(A37,'Appendix A'!A:A,'Appendix A'!E:E),"") -> 3.05 | C37: GasFromAbsorber | E37: =E36+E35 -> #N/A | F37: % | G37: =100*(E37-B37)/B37 -> #N/A | H37: Combined CO2 % in treated gas
A38: PI_100 | B38: =IFERROR(_xlfn.XLOOKUP(A38,'Appendix A'!A:A,'Appendix A'!E:E),"") -> 1040.05 | C38: 00PI100 | D38: 00PI100:MeasuredValue | E38: {=_xll.ReadKSpice(_xlfn.CONCAT("/",$B$1,"/",$B$2,"/",D38,"@V_Unit=",F38))} -> #N/A | F38: mbara | G38: =100*(E38-B38)/B38 -> #N/A
A39: PI_102 | B39: =IFERROR(_xlfn.XLOOKUP(A39,'Appendix A'!A:A,'Appendix A'!E:E),"") -> 1048.13 | C39: 00PI102 | D39: 00PI102:MeasuredValue | E39: {=_xll.ReadKSpice(_xlfn.CONCAT("/",$B$1,"/",$B$2,"/",D39,"@V_Unit=",F39))} -> #N/A | F39: mbara | G39: =100*(E39-B39)/B39 -> #N/A
A40: TAB | B40: =IFERROR(_xlfn.XLOOKUP(A40,'Appendix A'!A:A,'Appendix A'!E:E),"") -> 46.68 | C40: 00TAB000 | D40: 00TAB000:MeasuredValue | E40: {=_xll.ReadKSpice(_xlfn.CONCAT("/",$B$1,"/",$B$2,"/",D40,"@V_Unit=",F40))} -> #N/A | F40: degC | G40: =100*(E40-B40)/B40 -> #N/A | H40: Lik TV5? Det er samme transpimmer i K-spice
A41: TA00 | B41: =IFERROR(_xlfn.XLOOKUP(A41,'Appendix A'!A:A,'Appendix A'!E:E),"") -> 47.91 | C41: 00TA000 | D41: 00TA000:MeasuredValue | E41: {=_xll.ReadKSpice(_xlfn.CONCAT("/",$B$1,"/",$B$2,"/",D41,"@V_Unit=",F41))} -> #N/A | F41: degC | G41: =100*(E41-B41)/B41 -> #N/A
A42: TA01 | B42: =IFERROR(_xlfn.XLOOKUP(A42,'Appendix A'!A:A,'Appendix A'!E:E),"") -> 48.73 | C42: 00TA001 | D42: 00TA001:MeasuredValue | E42: {=_xll.ReadKSpice(_xlfn.CONCAT("/",$B$1,"/",$B$2,"/",D42,"@V_Unit=",F42))} -> #N/A | F42: degC | G42: =100*(E42-B42)/B42 -> #N/A
A43: TA02 | B43: =IFERROR(_xlfn.XLOOKUP(A43,'Appendix A'!A:A,'Appendix A'!E:E),"") -> 48.67 | C43: 00TA002 | D43: 00TA002:MeasuredValue | E43: {=_xll.ReadKSpice(_xlfn.CONCAT("/",$B$1,"/",$B$2,"/",D43,"@V_Unit=",F43))} -> #N/A | F43: degC | G43: =100*(E43-B43)/B43 -> #N/A
A44: TA03 | B44: =IFERROR(_xlfn.XLOOKUP(A44,'Appendix A'!A:A,'Appendix A'!E:E),"") -> 48.61 | C44: 00TA003 | D44: 00TA003:MeasuredValue | E44: {=_xll.ReadKSpice(_xlfn.CONCAT("/",$B$1,"/",$B$2,"/",D44,"@V_Unit=",F44))} -> #N/A | F44: degC | G44: =100*(E44-B44)/B44 -> #N/A
A45: TA04 | B45: =IFERROR(_xlfn.XLOOKUP(A45,'Appendix A'!A:A,'Appendix A'!E:E),"") -> 48.67 | C45: 00TA004 | D45: 00TA004:MeasuredValue | E45: {=_xll.ReadKSpice(_xlfn.CONCAT("/",$B$1,"/",$B$2,"/",D45,"@V_Unit=",F45))} -> #N/A | F45: degC | G45: =100*(E45-B45)/B45 -> #N/A
...

Sheet SS case 3 (v19.5)
A1: Timeline: | B1: Engineering
A2: Model server: | B2: ProcessModel
A4: Case: | B4: 3
A6: Fargevisning:
A7: Grønn: | B7: 0 | C7: 5
A8: Gul: | B8: 5 | C8: 10
A9: Rød: | B9: 10 | C9: 100 | F9: GJ KPI avvik: | G9: {=AVERAGE(ABS(G100:G103))} -> 5.0984884
F10: Gj. Avvik: | G10: {=AVERAGE(ABS(G26:G31),ABS(G34),ABS(G37:G49),ABS(G52),ABS(G55),ABS(G57:G58),ABS(G61:G68),ABS(G71:G76),ABS(G79),ABS(G80),ABS(G83),ABS(G85),ABS(G88),ABS(G91),ABS(G100:G102))} -> 9.1575025
A11: TAG in literature | B11: Value from Appendix A | C11: TAG in model | D11: Data-tag in model | E11: SimulatedValue | F11: unit | G11: % deviation | H11: Comment
A12: SETPOINTS SET IN MCL
A13: FT06 | B13: 127.02 | C13: 00FIC001 | D13: 00FIC001:InternalSetpoint | E13: 127.02 | F13: m3/h | G13: 0 | H13: Gas Flow Rate
A14: FT_100 | B14: 152.07 | C14: 00FC001 | D14: 00FC001:InternalSetpoint | E14: 152.1 | F14: kg/h | G14: 0.019727757 | H14: Solvent Flow Rate Lean input
A15: TA08 | B15: 57.95 | C15: LeanMEA_inn | D15: LeanMEA_inn:InstructorTemperature | E15: 57.95 | F15: degC | G15: -2.4522614e-14 | H15: Temperature Lean Solvent LeanMEA_inn
A16: TA08 | B16: 57.95 | C16: 02TIC002 | D16: 02TIC002:InternalSetpoint | E16: 57.95 | F16: degC | G16: -2.4522614e-14 | H16: Temperature Lean Solvent LeanMEA_ut
A17: HE_04/05/06 | B17: 10.02 | C17: 02QIC001 | D17: 02QIC001:InternalSetpoint | E17: 10 | F17: kW | G17: -0.1996008 | H17: Reboiler Duty
A18: TAB | B18: 46.68 | C18: 00TIC000 | D18: 00TIC000:InternalSetpoint | E18: 46.68 | F18: degC | G18: 1.5221567e-14 | H18: Absorber Inlet CO2 Temperature
B19: 0.22 | C19: LAL_IN | D19: LAL_IN:Output | E19: 0.21999454 | F19: mol/mol | G19: -0.0024806046 | H19: CO2 Loading Lean input
A20: PI_100 | B20: 1040.05 | C20: 00PIC002 | D20: 00PIC002:InternalSetpoint | E20: 1040.05 | F20: mbara | G20: 0 | H20: Pressure in absorber
A21: PT_02 | B21: 0.9 | C21: 04PIC001 | D21: 04PIC001:InternalSetpoint | E21: 0.9 | F21: barg | G21: 1.2335811e-14 | H21: Pressure in reboiler
A22: TT_01 | B22: 30.74 | C22: 03TIC001 | D22: 03TIC001:InternalSetpoint | E22: 30.74 | F22: degC | G22: 3.4671897e-14 | H22: EX03 cooling loop
A23: TT_02 | B23: 29.4 | C23: 04TIC001 | D23: 04TIC001:InternalSetpoint | E23: 29.4 | F23: degC | G23: -7.2504361e-14 | H23: EX04 cooling loop
A25: FLOW INTO ABSORBER
A26: FT06 | B26: 127.02 | C26: 00FT001 | D26: 00FT001:MeasuredValue | E26: 127.02 | F26: m3/h | G26: -1.5445774e-09
A27: PI_103 | B27: 1056.4 | C27: 00PT001 | D27: 00PT001:MeasuredValue | E27: 1044.9989 | F27: mbara | G27: -1.0792403
A28: TV5 | B28: 49.37 | C28: 00TAB000 | D28: 00TAB000:MeasuredValue | E28: 46.68 | F28: degC | G28: -5.448653
A29: FT_100 | B29: 152.07 | C29: 00FT003 | D29: 00FT003:MeasuredValue | E29: 152.1 | F29: kg/h | G29: 0.019727755
A30: TA08 | B30: 57.95 | C30: LeanAmineInput | D30: LeanAmineInput:OutletStream.t | E30: 57.955228 | F30: degC | G30: 0.0090212086 | H30: Temperature Lean Solvent LeanMEA_inn
A31: TA08 | B31: 57.95 | C31: 02TT002 | D31: 02TT002:MeasuredValue | E31: 33.330484 | F31: degC | G31: -42.484066 | H31: Temperature Lean Solvent LeanMEA_ut
A33: ABSORBER
A34: CO2_IN | B34: 7.41 | C34: GasToAbsorber | D34: GasToAbsorber:OutputCompositionVector[4] | E34: 7.7 | F34: % | G34: 3.9136302 | H34: % CO2
A35: CO2_OUT (Gas) | C35: GasFromAbsorber | D35: GasFromAbsorber:OutputCompositionVector[4] | E35: 2.9631055 | F35: % | H35: CO2 in gas form
A36: CO2_OUT (In MEA) | C36: GasFromAbsorber | D36: GasFromAbsorber:OutputCompositionVector[2] | E36: 0.13203555 | F36: % | H36: CO2 in MEA
A37: CO2_OUT | B37: 3.05 | C37: GasFromAbsorber | E37: 3.0951411 | F37: % | G37: 1.4800359 | H37: Combined CO2 % in treated gas
A38: PI_100 | B38: 1040.05 | C38: 00PI100 | D38: 00PI100:MeasuredValue | E38: 1040.05 | F38: mbara | G38: 9.8885304e-10
A39: PI_102 | B39: 1048.13 | C39: 00PI102 | D39: 00PI102:MeasuredValue | E39: 1044.6892 | F39: mbara | G39: -0.32827788
A40: TAB | B40: 46.68 | C40: 00TAB000 | D40: 00TAB000:MeasuredValue | E40: 46.68 | F40: degC | G40: 3.9119427e-12 | H40: Lik TV5? Det er samme transpimmer i K-spice
A41: TA00 | B41: 47.91 | C41: 00TA000 | D41: 00TA000:MeasuredValue | E41: 33.407467 | F41: degC | G41: -30.270368
A42: TA01 | B42: 48.73 | C42: 00TA001 | D42: 00TA001:MeasuredValue | E42: 33.379693 | F42: degC | G42: -31.500733
A43: TA02 | B43: 48.67 | C43: 00TA002 | D43: 00TA002:MeasuredValue | E43: 34.145114 | F43: degC | G43: -29.843612
A44: TA03 | B44: 48.61 | C44: 00TA003 | D44: 00TA003:MeasuredValue | E44: 35.143119 | F44: degC | G44: -27.70393
...

Sheet SS case 5
A1: Timeline: | B1: Engineering
A2: Model server: | B2: ProcessModel
A4: Case: | B4: 5
A6: Fargevisning:
A7: Grønn: | B7: 0 | C7: 5
A8: Gul: | B8: 5 | C8: 10
A9: Rød: | B9: 10 | C9: 100
A11: TAG in literature | B11: Value from Appendix A | C11: TAG in model | D11: Data-tag in model | E11: SimulatedValue | F11: unit | G11: % deviation | H11: Comment
A12: SETPOINTS SET IN MCL
A13: FT06 | B13: =IFERROR(_xlfn.XLOOKUP(A13,'Appendix A'!A:A,'Appendix A'!G:G),"") -> 125.94 | C13: 00FIC001 | D13: 00FIC001:InternalSetpoint | E13: {=_xll.ReadKSpice(_xlfn.CONCAT("/",$B$1,"/",$B$2,"/",D13,"@V_Unit=",F13))} -> #N/A | F13: m3/h | G13: =100*(E13-B13)/B13 -> #N/A | H13: Gas Flow Rate
A14: FT_100 | B14: =IFERROR(_xlfn.XLOOKUP(A14,'Appendix A'!A:A,'Appendix A'!G:G),"") -> 240.87 | C14: 00FC001 | D14: 00FC001:InternalSetpoint | E14: {=_xll.ReadKSpice(_xlfn.CONCAT("/",$B$1,"/",$B$2,"/",D14,"@V_Unit=",F14))} -> #N/A | F14: kg/h | G14: =100*(E14-B14)/B14 -> #N/A | H14: Solvent Flow Rate Lean input
A15: TA08 | B15: =IFERROR(_xlfn.XLOOKUP(A15,'Appendix A'!A:A,'Appendix A'!G:G),"") -> 52.17 | C15: LeanMEA_inn | D15: LeanMEA_inn:InstructorTemperature | E15: {=_xll.ReadKSpice(_xlfn.CONCAT("/",$B$1,"/",$B$2,"/",D15,"@V_Unit=",F15))} -> #N/A | F15: degC | G15: =100*(E15-B15)/B15 -> #N/A | H15: Temperature Lean Solvent LeanMEA_inn
A16: TA08 | B16: =IFERROR(_xlfn.XLOOKUP(A16,'Appendix A'!A:A,'Appendix A'!G:G),"") -> 52.17 | C16: 02TIC002 | D16: 02TIC002:InternalSetpoint | E16: {=_xll.ReadKSpice(_xlfn.CONCAT("/",$B$1,"/",$B$2,"/",D16,"@V_Unit=",F16))} -> #N/A | F16: degC | G16: =100*(E16-B16)/B16 -> #N/A | H16: Temperature Lean Solvent LeanMEA_ut
A17: HE_04/05/06 | B17: =IFERROR(_xlfn.XLOOKUP(A17,'Appendix A'!A:A,'Appendix A'!G:G),"") -> 10.35 | C17: 02QIC001 | D17: 02QIC001:InternalSetpoint | E17: {=_xll.ReadKSpice(_xlfn.CONCAT("/",$B$1,"/",$B$2,"/",D17,"@V_Unit=",F17))} -> #N/A | F17: kW | G17: =100*(E17-B17)/B17 -> #N/A | H17: Reboiler Duty
A18: TAB | B18: =IFERROR(_xlfn.XLOOKUP(A18,'Appendix A'!A:A,'Appendix A'!G:G),"") -> 44.38 | C18: 00TIC000 | D18: 00TIC000:InternalSetpoint | E18: {=_xll.ReadKSpice(_xlfn.CONCAT("/",$B$1,"/",$B$2,"/",D18,"@V_Unit=",F18))} -> #N/A | F18: degC | G18: =100*(E18-B18)/B18 -> #N/A | H18: Absorber Inlet CO2 Temperature
B19: 0.27 | C19: LAL_IN | D19: LAL_IN:Output | E19: {=_xll.ReadKSpice(_xlfn.CONCAT("/",$B$1,"/",$B$2,"/",D19,"@V_Unit=",F19))} -> #N/A | F19: mol/mol | G19: =100*(E19-B19)/B19 -> #N/A | H19: CO2 Loading Lean input
A20: PI_100 | B20: =IFERROR(_xlfn.XLOOKUP(A20,'Appendix A'!A:A,'Appendix A'!G:G),"") -> 1012.1 | C20: 00PIC002 | D20: 00PIC002:InternalSetpoint | E20: {=_xll.ReadKSpice(_xlfn.CONCAT("/",$B$1,"/",$B$2,"/",D20,"@V_Unit=",F20))} -> #N/A | F20: mbara | G20: =100*(E20-B20)/B20 -> #N/A | H20: Pressure in absorber
A21: PT_02 | B21: =IFERROR(_xlfn.XLOOKUP(A21,'Appendix A'!A:A,'Appendix A'!G:G),"") -> 0.9 | C21: 04PIC001 | D21: 04PIC001:InternalSetpoint | E21: {=_xll.ReadKSpice(_xlfn.CONCAT("/",$B$1,"/",$B$2,"/",D21,"@V_Unit=",F21))} -> #N/A | F21: barg | G21: =100*(E21-B21)/B21 -> #N/A | H21: Pressure in reboiler
A22: TT_01 | B22: =IFERROR(_xlfn.XLOOKUP(A22,'Appendix A'!A:A,'Appendix A'!G:G),"") -> 30.62 | C22: 03TIC001 | D22: 03TIC001:InternalSetpoint | E22: {=_xll.ReadKSpice(_xlfn.CONCAT("/",$B$1,"/",$B$2,"/",D22,"@V_Unit=",F22))} -> #N/A | F22: degC | G22: =100*(E22-B22)/B22 -> #N/A | H22: EX03 cooling loop
A23: TT_02 | B23: =IFERROR(_xlfn.XLOOKUP(A23,'Appendix A'!A:A,'Appendix A'!G:G),"") -> 25.99 | C23: 04TIC001 | D23: 04TIC001:InternalSetpoint | E23: {=_xll.ReadKSpice(_xlfn.CONCAT("/",$B$1,"/",$B$2,"/",D23,"@V_Unit=",F23))} -> #N/A | F23: degC | G23: =100*(E23-B23)/B23 -> #N/A | H23: EX04 cooling loop
A25: FLOW INTO ABSORBER
A26: FT06 | B26: =IFERROR(_xlfn.XLOOKUP(A26,'Appendix A'!A:A,'Appendix A'!G:G),"") -> 125.94 | C26: 00FT001 | D26: 00FT001:MeasuredValue | E26: {=_xll.ReadKSpice(_xlfn.CONCAT("/",$B$1,"/",$B$2,"/",D26,"@V_Unit=",F26))} -> #N/A | F26: m3/h | G26: =100*(E26-B26)/B26 -> #N/A
A27: PI_103 | B27: =IFERROR(_xlfn.XLOOKUP(A27,'Appendix A'!A:A,'Appendix A'!G:G),"") -> 1029 | C27: 00PT001 | D27: 00PT001:MeasuredValue | E27: {=_xll.ReadKSpice(_xlfn.CONCAT("/",$B$1,"/",$B$2,"/",D27,"@V_Unit=",F27))} -> #N/A | F27: mbara | G27: =100*(E27-B27)/B27 -> #N/A
A28: TV5 | B28: =IFERROR(_xlfn.XLOOKUP(A28,'Appendix A'!A:A,'Appendix A'!G:G),"") -> 47.16 | C28: 00TAB000 | D28: 00TAB000:MeasuredValue | E28: {=_xll.ReadKSpice(_xlfn.CONCAT("/",$B$1,"/",$B$2,"/",D28,"@V_Unit=",F28))} -> #N/A | F28: degC | G28: =100*(E28-B28)/B28 -> #N/A
A29: FT_100 | B29: =IFERROR(_xlfn.XLOOKUP(A29,'Appendix A'!A:A,'Appendix A'!G:G),"") -> 240.87 | C29: 00FT003 | D29: 00FT003:MeasuredValue | E29: {=_xll.ReadKSpice(_xlfn.CONCAT("/",$B$1,"/",$B$2,"/",D29,"@V_Unit=",F29))} -> #N/A | F29: kg/h | G29: =100*(E29-B29)/B29 -> #N/A
A30: TA08 | B30: =IFERROR(_xlfn.XLOOKUP(A30,'Appendix A'!A:A,'Appendix A'!G:G),"") -> 52.17 | C30: LeanAmineInput | D30: LeanAmineInput:OutletStream.t | E30: {=_xll.ReadKSpice(_xlfn.CONCAT("/",$B$1,"/",$B$2,"/",D30,"@V_Unit=",F30))} -> #N/A | F30: degC | G30: =100*(E30-B30)/B30 -> #N/A | H30: Temperature Lean Solvent LeanMEA_inn
A31: TA08 | B31: =IFERROR(_xlfn.XLOOKUP(A31,'Appendix A'!A:A,'Appendix A'!G:G),"") -> 52.17 | C31: 02TT002 | D31: 02TT002:MeasuredValue | E31: {=_xll.ReadKSpice(_xlfn.CONCAT("/",$B$1,"/",$B$2,"/",D31,"@V_Unit=",F31))} -> #N/A | F31: degC | G31: =100*(E31-B31)/B31 -> #N/A | H31: Temperature Lean Solvent LeanMEA_ut
A33: ABSORBER
A34: CO2_IN | B34: =IFERROR(_xlfn.XLOOKUP(A34,'Appendix A'!A:A,'Appendix A'!G:G),"") -> 3.9 | C34: GasToAbsorber | D34: GasToAbsorber:OutputCompositionVector[4] | E34: {=_xll.ReadKSpice(_xlfn.CONCAT("/",$B$1,"/",$B$2,"/",D34,"@V_Unit=",F34))} -> #N/A | F34: % | G34: =100*(E34-B34)/B34 -> #N/A | H34: % CO2
A35: CO2_OUT (Gas) | B35: =IFERROR(_xlfn.XLOOKUP(A35,'Appendix A'!A:A,'Appendix A'!D:D),"") | C35: GasFromAbsorber | D35: GasFromAbsorber:OutputCompositionVector[4] | E35: {=_xll.ReadKSpice(_xlfn.CONCAT("/",$B$1,"/",$B$2,"/",D35,"@V_Unit=",F35))} -> #N/A | F35: % | H35: CO2 in gas form
A36: CO2_OUT (In MEA) | B36: =IFERROR(_xlfn.XLOOKUP(A36,'Appendix A'!A:A,'Appendix A'!D:D),"") | C36: GasFromAbsorber | D36: GasFromAbsorber:OutputCompositionVector[2] | E36: {=_xll.ReadKSpice(_xlfn.CONCAT("/",$B$1,"/",$B$2,"/",D36,"@V_Unit=",F36))} -> #N/A | F36: % | H36: CO2 in MEA
A37: CO2_OUT | B37: =IFERROR(_xlfn.XLOOKUP(A37,'Appendix A'!A:A,'Appendix A'!G:G),"") -> 0.44 | C37: GasFromAbsorber | E37: =E36+E35 -> #N/A | F37: % | G37: =100*(E37-B37)/B37 -> #N/A | H37: Combined CO2 % in treated gas
A38: PI_100 | B38: =IFERROR(_xlfn.XLOOKUP(A38,'Appendix A'!A:A,'Appendix A'!G:G),"") -> 1012.1 | C38: 00PI100 | D38: 00PI100:MeasuredValue | E38: {=_xll.ReadKSpice(_xlfn.CONCAT("/",$B$1,"/",$B$2,"/",D38,"@V_Unit=",F38))} -> #N/A | F38: mbara | G38: =100*(E38-B38)/B38 -> #N/A
A39: PI_102 | B39: =IFERROR(_xlfn.XLOOKUP(A39,'Appendix A'!A:A,'Appendix A'!G:G),"") -> 1020.73 | C39: 00PI102 | D39: 00PI102:MeasuredValue | E39: {=_xll.ReadKSpice(_xlfn.CONCAT("/",$B$1,"/",$B$2,"/",D39,"@V_Unit=",F39))} -> #N/A | F39: mbara | G39: =100*(E39-B39)/B39 -> #N/A
A40: TAB | B40: =IFERROR(_xlfn.XLOOKUP(A40,'Appendix A'!A:A,'Appendix A'!G:G),"") -> 44.38 | C40: 00TAB000 | D40: 00TAB000:MeasuredValue | E40: {=_xll.ReadKSpice(_xlfn.CONCAT("/",$B$1,"/",$B$2,"/",D40,"@V_Unit=",F40))} -> #N/A | F40: degC | G40: =100*(E40-B40)/B40 -> #N/A | H40: Lik TV5? Det er samme transpimmer i K-spice
A41: TA00 | B41: =IFERROR(_xlfn.XLOOKUP(A41,'Appendix A'!A:A,'Appendix A'!G:G),"") -> 45.55 | C41: 00TA000 | D41: 00TA000:MeasuredValue | E41: {=_xll.ReadKSpice(_xlfn.CONCAT("/",$B$1,"/",$B$2,"/",D41,"@V_Unit=",F41))} -> #N/A | F41: degC | G41: =100*(E41-B41)/B41 -> #N/A
A42: TA01 | B42: =IFERROR(_xlfn.XLOOKUP(A42,'Appendix A'!A:A,'Appendix A'!G:G),"") -> 47.05 | C42: 00TA001 | D42: 00TA001:MeasuredValue | E42: {=_xll.ReadKSpice(_xlfn.CONCAT("/",$B$1,"/",$B$2,"/",D42,"@V_Unit=",F42))} -> #N/A | F42: degC | G42: =100*(E42-B42)/B42 -> #N/A
A43: TA02 | B43: =IFERROR(_xlfn.XLOOKUP(A43,'Appendix A'!A:A,'Appendix A'!G:G),"") -> 50.02 | C43: 00TA002 | D43: 00TA002:MeasuredValue | E43: {=_xll.ReadKSpice(_xlfn.CONCAT("/",$B$1,"/",$B$2,"/",D43,"@V_Unit=",F43))} -> #N/A | F43: degC | G43: =100*(E43-B43)/B43 -> #N/A
A44: TA03 | B44: =IFERROR(_xlfn.XLOOKUP(A44,'Appendix A'!A:A,'Appendix A'!G:G),"") -> 51.8 | C44: 00TA003 | D44: 00TA003:MeasuredValue | E44: {=_xll.ReadKSpice(_xlfn.CONCAT("/",$B$1,"/",$B$2,"/",D44,"@V_Unit=",F44))} -> #N/A | F44: degC | G44: =100*(E44-B44)/B44 -> #N/A
A45: TA04 | B45: =IFERROR(_xlfn.XLOOKUP(A45,'Appendix A'!A:A,'Appendix A'!G:G),"") -> 53.27 | C45: 00TA004 | D45: 00TA004:MeasuredValue | E45: {=_xll.ReadKSpice(_xlfn.CONCAT("/",$B$1,"/",$B$2,"/",D45,"@V_Unit=",F45))} -> #N/A | F45: degC | G45: =100*(E45-B45)/B45 -> #N/A
...

Sheet SS case 5 (v19.5)
A1: Timeline: | B1: Engineering
A2: Model server: | B2: ProcessModel
A4: Case: | B4: 5
A6: Fargevisning:
A7: Grønn: | B7: 0 | C7: 5
A8: Gul: | B8: 5 | C8: 10
A9: Rød: | B9: 10 | C9: 100 | F9: GJ KPI avvik: | G9: {=AVERAGE(ABS(G100:G103))} -> 7.2986775
F10: Gj. Avvik: | G10: {=AVERAGE(ABS(G26:G31),ABS(G34),ABS(G37:G49),ABS(G52),ABS(G55),ABS(G57:G58),ABS(G61:G68),ABS(G71:G76),ABS(G79),ABS(G80),ABS(G83),ABS(G85),ABS(G88),ABS(G91),ABS(G100:G102))} -> 5.6683996
A11: TAG in literature | B11: Value from Appendix A | C11: TAG in model | D11: Data-tag in model | E11: SimulatedValue | F11: unit | G11: % deviation | H11: Comment
A12: SETPOINTS SET IN MCL
A13: FT06 | B13: 125.94 | C13: 00FIC001 | D13: 00FIC001:InternalSetpoint | E13: 125.94 | F13: m3/h | G13: 0 | H13: Gas Flow Rate
A14: FT_100 | B14: 240.87 | C14: 00FC001 | D14: 00FC001:InternalSetpoint | E14: 240.9 | F14: kg/h | G14: 0.012454851 | H14: Solvent Flow Rate Lean input
A15: TA08 | B15: 52.17 | C15: LeanMEA_inn | D15: LeanMEA_inn:InstructorTemperature | E15: 52.17 | F15: degC | G15: 2.7239515e-14 | H15: Temperature Lean Solvent LeanMEA_inn
A16: TA08 | B16: 52.17 | C16: 02TIC002 | D16: 02TIC002:InternalSetpoint | E16: 52.17 | F16: degC | G16: 2.7239515e-14 | H16: Temperature Lean Solvent LeanMEA_ut
A17: HE_04/05/06 | B17: 10.35 | C17: 02QIC001 | D17: 02QIC001:InternalSetpoint | E17: 10.4 | F17: kW | G17: 0.48309179 | H17: Reboiler Duty
A18: TAB | B18: 44.38 | C18: 00TIC000 | D18: 00TIC000:InternalSetpoint | E18: 44.38 | F18: degC | G18: -1.6010427e-14 | H18: Absorber Inlet CO2 Temperature
B19: 0.27 | C19: LAL_IN | D19: LAL_IN:Output | E19: 0.2699839 | F19: mol/mol | G19: -0.0059645917 | H19: CO2 Loading Lean input
A20: PI_100 | B20: 1012.1 | C20: 00PIC002 | D20: 00PIC002:InternalSetpoint | E20: 1012.1 | F20: mbara | G20: 0 | H20: Pressure in absorber
A21: PT_02 | B21: 0.9 | C21: 04PIC001 | D21: 04PIC001:InternalSetpoint | E21: 0.9 | F21: barg | G21: 1.2335811e-14 | H21: Pressure in reboiler
A22: TT_01 | B22: 30.62 | C22: 03TIC001 | D22: 03TIC001:InternalSetpoint | E22: 30.62 | F22: degC | G22: 1.1602592e-14 | H22: EX03 cooling loop
A23: TT_02 | B23: 25.99 | C23: 04TIC001 | D23: 04TIC001:InternalSetpoint | E23: 25.99 | F23: degC | G23: 4.1008623e-14 | H23: EX04 cooling loop
A25: FLOW INTO ABSORBER
A26: FT06 | B26: 125.94 | C26: 00FT001 | D26: 00FT001:MeasuredValue | E26: 125.94 | F26: m3/h | G26: 1.2063231e-07
A27: PI_103 | B27: 1029 | C27: 00PT001 | D27: 00PT001:MeasuredValue | E27: 1019.3269 | F27: mbara | G27: -0.94004737
A28: TV5 | B28: 47.16 | C28: 00TAB000 | D28: 00TAB000:MeasuredValue | E28: 44.38 | F28: degC | G28: -5.8948261
A29: FT_100 | B29: 240.87 | C29: 00FT003 | D29: 00FT003:MeasuredValue | E29: 240.9 | F29: kg/h | G29: 0.012454868
A30: TA08 | B30: 52.17 | C30: LeanAmineInput | D30: LeanAmineInput:OutletStream.t | E30: 52.17565 | F30: degC | G30: 0.010830614 | H30: Temperature Lean Solvent LeanMEA_inn
A31: TA08 | B31: 52.17 | C31: 02TT002 | D31: 02TT002:MeasuredValue | E31: 45 | F31: degC | G31: -13.743531 | H31: Temperature Lean Solvent LeanMEA_ut
A33: ABSORBER
A34: CO2_IN | B34: 3.9 | C34: GasToAbsorber | D34: GasToAbsorber:OutputCompositionVector[4] | E34: 4.052002 | F34: % | G34: 3.8974861 | H34: % CO2
A35: CO2_OUT (Gas) | C35: GasFromAbsorber | D35: GasFromAbsorber:OutputCompositionVector[4] | E35: 0.10442056 | F35: % | H35: CO2 in gas form
A36: CO2_OUT (In MEA) | C36: GasFromAbsorber | D36: GasFromAbsorber:OutputCompositionVector[2] | E36: 0.068256438 | F36: % | H36: CO2 in MEA
A37: CO2_OUT | B37: 0.44 | C37: GasFromAbsorber | E37: 0.17267699 | F37: % | G37: -60.755229 | H37: Combined CO2 % in treated gas
A38: PI_100 | B38: 1012.1 | C38: 00PI100 | D38: 00PI100:MeasuredValue | E38: 1013.9363 | F38: mbara | G38: 0.18143254
A39: PI_102 | B39: 1020.73 | C39: 00PI102 | D39: 00PI102:MeasuredValue | E39: 1018.9955 | F39: mbara | G39: -0.16993061
A40: TAB | B40: 44.38 | C40: 00TAB000 | D40: 00TAB000:MeasuredValue | E40: 44.38 | F40: degC | G40: -3.4297056e-09 | H40: Lik TV5? Det er samme transpimmer i K-spice
A41: TA00 | B41: 45.55 | C41: 00TA000 | D41: 00TA000:MeasuredValue | E41: 45.446314 | F41: degC | G41: -0.22763189
A42: TA01 | B42: 47.05 | C42: 00TA001 | D42: 00TA001:MeasuredValue | E42: 45.40201 | F42: degC | G42: -3.5026355
A43: TA02 | B43: 50.02 | C43: 00TA002 | D43: 00TA002:MeasuredValue | E43: 52.59848 | F43: degC | G43: 5.1548974
A44: TA03 | B44: 51.8 | C44: 00TA003 | D44: 00TA003:MeasuredValue | E44: 52.748095 | F44: degC | G44: 1.8302989
...

Sheet SS case 6
A1: Timeline: | B1: Engineering
A2: Model server: | B2: ProcessModel
A4: Case: | B4: 6
A6: Fargevisning:
A7: Grønn: | B7: 0 | C7: 5
A8: Gul: | B8: 5 | C8: 10
A9: Rød: | B9: 10 | C9: 100
A11: TAG in literature | B11: Value from Appendix A | C11: TAG in model | D11: Data-tag in model | E11: SimulatedValue | F11: unit | G11: % deviation | H11: Comment
A12: SETPOINTS SET IN MCL
A13: FT06 | B13: =IFERROR(_xlfn.XLOOKUP(A13,'Appendix A'!A:A,'Appendix A'!H:H),"") -> 118.96 | C13: 00FIC001 | D13: 00FIC001:InternalSetpoint | E13: {=_xll.ReadKSpice(_xlfn.CONCAT("/",$B$1,"/",$B$2,"/",D13,"@V_Unit=",F13))} -> #N/A | F13: m3/h | G13: =100*(E13-B13)/B13 -> #N/A | H13: Gas Flow Rate
A14: FT_100 | B14: =IFERROR(_xlfn.XLOOKUP(A14,'Appendix A'!A:A,'Appendix A'!H:H),"") -> 178.72 | C14: 00FC001 | D14: 00FC001:InternalSetpoint | E14: {=_xll.ReadKSpice(_xlfn.CONCAT("/",$B$1,"/",$B$2,"/",D14,"@V_Unit=",F14))} -> #N/A | F14: kg/h | G14: =100*(E14-B14)/B14 -> #N/A | H14: Solvent Flow Rate Lean input
A15: TA08 | B15: =IFERROR(_xlfn.XLOOKUP(A15,'Appendix A'!A:A,'Appendix A'!H:H),"") -> 46.94 | C15: LeanMEA_inn | D15: LeanMEA_inn:InstructorTemperature | E15: {=_xll.ReadKSpice(_xlfn.CONCAT("/",$B$1,"/",$B$2,"/",D15,"@V_Unit=",F15))} -> #N/A | F15: degC | G15: =100*(E15-B15)/B15 -> #N/A | H15: Temperature Lean Solvent LeanMEA_inn
A16: TA08 | B16: =IFERROR(_xlfn.XLOOKUP(A16,'Appendix A'!A:A,'Appendix A'!H:H),"") -> 46.94 | C16: 02TIC002 | D16: 02TIC002:InternalSetpoint | E16: {=_xll.ReadKSpice(_xlfn.CONCAT("/",$B$1,"/",$B$2,"/",D16,"@V_Unit=",F16))} -> #N/A | F16: degC | G16: =100*(E16-B16)/B16 -> #N/A | H16: Temperature Lean Solvent LeanMEA_ut
A17: HE_04/05/06 | B17: =IFERROR(_xlfn.XLOOKUP(A17,'Appendix A'!A:A,'Appendix A'!H:H),"") -> 6.13 | C17: 02QIC001 | D17: 02QIC001:InternalSetpoint | E17: {=_xll.ReadKSpice(_xlfn.CONCAT("/",$B$1,"/",$B$2,"/",D17,"@V_Unit=",F17))} -> #N/A | F17: kW | G17: =100*(E17-B17)/B17 -> #N/A | H17: Reboiler Duty
A18: TAB | B18: =IFERROR(_xlfn.XLOOKUP(A18,'Appendix A'!A:A,'Appendix A'!H:H),"") -> 38.93 | C18: 00TIC000 | D18: 00TIC000:InternalSetpoint | E18: {=_xll.ReadKSpice(_xlfn.CONCAT("/",$B$1,"/",$B$2,"/",D18,"@V_Unit=",F18))} -> #N/A | F18: degC | G18: =100*(E18-B18)/B18 -> #N/A | H18: Absorber Inlet CO2 Temperature
B19: 0.34 | C19: LAL_IN | D19: LAL_IN:Output | E19: {=_xll.ReadKSpice(_xlfn.CONCAT("/",$B$1,"/",$B$2,"/",D19,"@V_Unit=",F19))} -> #N/A | F19: mol/mol | G19: =100*(E19-B19)/B19 -> #N/A | H19: CO2 Loading Lean input
A20: PI_100 | B20: =IFERROR(_xlfn.XLOOKUP(A20,'Appendix A'!A:A,'Appendix A'!H:H),"") -> 1030.53 | C20: 00PIC002 | D20: 00PIC002:InternalSetpoint | E20: {=_xll.ReadKSpice(_xlfn.CONCAT("/",$B$1,"/",$B$2,"/",D20,"@V_Unit=",F20))} -> #N/A | F20: mbara | G20: =100*(E20-B20)/B20 -> #N/A | H20: Pressure in absorber
A21: PT_02 | B21: =IFERROR(_xlfn.XLOOKUP(A21,'Appendix A'!A:A,'Appendix A'!H:H),"") -> 0.7 | C21: 04PIC001 | D21: 04PIC001:InternalSetpoint | E21: {=_xll.ReadKSpice(_xlfn.CONCAT("/",$B$1,"/",$B$2,"/",D21,"@V_Unit=",F21))} -> #N/A | F21: barg | G21: =100*(E21-B21)/B21 -> #N/A | H21: Pressure in reboiler
A22: TT_01 | B22: =IFERROR(_xlfn.XLOOKUP(A22,'Appendix A'!A:A,'Appendix A'!H:H),"") -> 30.63 | C22: 03TIC001 | D22: 03TIC001:InternalSetpoint | E22: {=_xll.ReadKSpice(_xlfn.CONCAT("/",$B$1,"/",$B$2,"/",D22,"@V_Unit=",F22))} -> #N/A | F22: degC | G22: =100*(E22-B22)/B22 -> #N/A | H22: EX03 cooling loop
